Workbook
Name Weekdays: 下拉列表V3!$A$2:$A$31
Name CarbFoods: 下拉列表V3!$B$2:$B$31
Name ProteinFoods: 下拉列表V3!$C$2:$C$31
Name FatFoods: 下拉列表V3!$D$2:$D$31
Name VegFoods: 下拉列表V3!$E$2:$E$31
Name CycleDays: 下拉列表V3!$F$2:$F$32
Name CycleTypes: 下拉列表V3!$G$2:$G$4
Name YesNo: 下拉列表V3!$H$2:$H$3
Name TrainingTimes: 下拉列表V3!$I$2:$I$6
Name CycleLength: V6周期计划!$B$9

Sheet V6周期计划
A1: 碳循环减脂计划计算器 V6｜1～31天自定义循环
A3: ① 基础参数与循环长度（黄色单元格可修改）
A4: 体重（kg） | B4: 85 | C4: 当前体重；TDEE页会自动关联
A5: 基础碳水（g/kg/天） | B5: 2 | C5: 用于计算整个循环的碳水总量
A6: 蛋白质（g/kg/天） | B6: 1.4 | C6: 每个循环日固定
A7: 基础脂肪（g/kg/天） | B7: 0.8 | C7: 用于计算默认计划日均热量
A8: 计划日均热量（kcal） | B8: =B4*(B5*4+B6*4+B7*9) -> 1768 | C8: 脂肪按日反向计算；也可直接改成目标热量
A9: 循环长度（天） | B9: 7 | C9: 允许1～31天；默认保留原7天安排
A11: ② 高/中/低碳分配（按实际天数和强度权重自动归一化）
A12: 类型 | B12: 有效天数 | C12: 单日强度权重 | D12: 自动循环占比 | E12: 该类型循环碳水(g) | F12: 每个该类日碳水(g) | G12: 碳水(g/kg) | H12: 每类日脂肪(g) | I12: 状态 | J12: 周期汇总
A13: 高碳日 | B13: =COUNTIFS($A$20:$A$50,"<="&$B$9,$C$20:$C$50,A13) -> 2 | C13: 1.6 | D13: =IF(SUMPRODUCT($B$13:$B$15,$C$13:$C$15)=0,0,B13*C13/SUMPRODUCT($B$13:$B$15,$C$13:$C$15)) -> 0.45070423 | E13: =$B$4*$B$5*$B$9*D13 -> 536.33803 | F13: =IF(B13=0,0,E13/B13) -> 268.16901 | G13: =IF($B$4=0,0,F13/$B$4) -> 3.1549296 | H13: =MAX(0,($B$8-F13*4-$B$4*$B$6*4)/9) -> 24.369327 | I13: =IF(B13=0,"未使用",IF(C13<=0,"权重需大于0",IF(H13=0,"脂肪为0：提高热量","正常"))) -> 正常 | J13: 周期总碳水(g) | K13: =SUM(G20:G50) -> 1190 | L13: 日均热量 | M13: =IF($B$9=0,0,K16/$B$9) -> 1768
A14: 中碳日 | B14: =COUNTIFS($A$20:$A$50,"<="&$B$9,$C$20:$C$50,A14) -> 3 | C14: 0.9 | D14: =IF(SUMPRODUCT($B$13:$B$15,$C$13:$C$15)=0,0,B14*C14/SUMPRODUCT($B$13:$B$15,$C$13:$C$15)) -> 0.38028169 | E14: =$B$4*$B$5*$B$9*D14 -> 452.53521 | F14: =IF(B14=0,0,E14/B14) -> 150.84507 | G14: =IF($B$4=0,0,F14/$B$4) -> 1.7746479 | H14: =MAX(0,($B$8-F14*4-$B$4*$B$6*4)/9) -> 76.513302 | I14: =IF(B14=0,"未使用",IF(C14<=0,"权重需大于0",IF(H14=0,"脂肪为0：提高热量","正常"))) -> 正常 | J14: 周期总蛋白(g) | K14: =SUM(H20:H50) -> 833 | L14: 训练日 | M14: =COUNTIFS($A$20:$A$50,"<="&$B$9,$D$20:$D$50,"是") -> 4
A15: 低碳日 | B15: =COUNTIFS($A$20:$A$50,"<="&$B$9,$C$20:$C$50,A15) -> 2 | C15: 0.6 | D15: =IF(SUMPRODUCT($B$13:$B$15,$C$13:$C$15)=0,0,B15*C15/SUMPRODUCT($B$13:$B$15,$C$13:$C$15)) -> 0.16901408 | E15: =$B$4*$B$5*$B$9*D15 -> 201.12676 | F15: =IF(B15=0,0,E15/B15) -> 100.56338 | G15: =IF($B$4=0,0,F15/$B$4) -> 1.1830986 | H15: =MAX(0,($B$8-F15*4-$B$4*$B$6*4)/9) -> 98.86072 | I15: =IF(B15=0,"未使用",IF(C15<=0,"权重需大于0",IF(H15=0,"脂肪为0：提高热量","正常"))) -> 正常 | J15: 周期总脂肪(g) | K15: =SUM(I20:I50) -> 476 | L15: 休息日 | M15: =COUNTIFS($A$20:$A$50,"<="&$B$9,$D$20:$D$50,"否") -> 3
A16: 权重检查 | B16: =IF(SUMPRODUCT(B13:B15,C13:C15)>0,"通过","需设置有效权重") -> 通过 | D16: 已配置天数 | E16: =COUNTIFS($A$20:$A$50,"<="&$B$9,$C$20:$C$50,"<>") -> 7 | F16: 周期长度 | G16: =$B$9 -> 7 | H16: 配置检查 | I16: =IF(E16=G16,"通过","有未配置日") -> 通过 | J16: 周期总热量(kcal) | K16: =SUM(J20:J50) -> 12376 | L16: 配置状态 | M16: =IF(AND(B16="通过",I16="通过"),"可用","请检查") -> 可用
A18: ③ 循环日配置与每日营养目标（黄色列可逐日修改）
A19: 循环日 | B19: 显示名称 | C19: 碳循环类型 | D19: 是否训练 | E19: 训练时间 | F19: 餐食模板 | G19: 碳水(g) | H19: 蛋白质(g) | I19: 脂肪(g) | J19: 总热量(kcal) | K19: 碳水(g/kg) | L19: 脂肪(g/kg) | M19: 状态
A20: 1 | B20: =IF(A20<=$B$9,"第"&A20&"天","未启用") -> 第1天 | C20: 中碳日 | D20: 是 | E20: 晚饭前 | F20: =IF(A20>$B$9,"",IF(D20="是","训练日模板",IF(D20="否","休息日模板","待设置"))) -> 训练日模板 | G20: =IF(A20>$B$9,"",IFERROR(INDEX($F$13:$F$15,MATCH(C20,$A$13:$A$15,0)),"")) -> 150.84507 | H20: =IF(A20>$B$9,"",$B$4*$B$6) -> 119 | I20: =IF(A20>$B$9,"",IFERROR(INDEX($H$13:$H$15,MATCH(C20,$A$13:$A$15,0)),"")) -> 76.513302 | J20: =IF(A20>$B$9,"",IF(OR(G20="",H20="",I20=""),"",G20*4+H20*4+I20*9)) -> 1768 | K20: =IF(OR(A20>$B$9,$B$4=0),"",G20/$B$4) -> 1.7746479 | L20: =IF(OR(A20>$B$9,$B$4=0),"",I20/$B$4) -> 0.90015649 | M20: =IF(A20>$B$9,"未启用",IF(C20="","需设置碳类型",IF(AND(D20<>"是",D20<>"否"),"需设置训练",IF(AND(D20="是",OR(E20="",E20="-")),"请填训练时间",IF(AND(D20="否",E20<>"-"),"休息日时间应为-",IF(I20=0,"脂肪为0：提高热量","正常")))))) -> 正常
A21: 2 | B21: =IF(A21<=$B$9,"第"&A21&"天","未启用") -> 第2天 | C21: 低碳日 | D21: 否 | E21: - | F21: =IF(A21>$B$9,"",IF(D21="是","训练日模板",IF(D21="否","休息日模板","待设置"))) -> 休息日模板 | G21: =IF(A21>$B$9,"",IFERROR(INDEX($F$13:$F$15,MATCH(C21,$A$13:$A$15,0)),"")) -> 100.56338 | H21: =IF(A21>$B$9,"",$B$4*$B$6) -> 119 | I21: =IF(A21>$B$9,"",IFERROR(INDEX($H$13:$H$15,MATCH(C21,$A$13:$A$15,0)),"")) -> 98.86072 | J21: =IF(A21>$B$9,"",IF(OR(G21="",H21="",I21=""),"",G21*4+H21*4+I21*9)) -> 1768 | K21: =IF(OR(A21>$B$9,$B$4=0),"",G21/$B$4) -> 1.1830986 | L21: =IF(OR(A21>$B$9,$B$4=0),"",I21/$B$4) -> 1.1630673 | M21: =IF(A21>$B$9,"未启用",IF(C21="","需设置碳类型",IF(AND(D21<>"是",D21<>"否"),"需设置训练",IF(AND(D21="是",OR(E21="",E21="-")),"请填训练时间",IF(AND(D21="否",E21<>"-"),"休息日时间应为-",IF(I21=0,"脂肪为0：提高热量","正常")))))) -> 正常
A22: 3 | B22: =IF(A22<=$B$9,"第"&A22&"天","未启用") -> 第3天 | C22: 中碳日 | D22: 是 | E22: 晚饭前 | F22: =IF(A22>$B$9,"",IF(D22="是","训练日模板",IF(D22="否","休息日模板","待设置"))) -> 训练日模板 | G22: =IF(A22>$B$9,"",IFERROR(INDEX($F$13:$F$15,MATCH(C22,$A$13:$A$15,0)),"")) -> 150.84507 | H22: =IF(A22>$B$9,"",$B$4*$B$6) -> 119 | I22: =IF(A22>$B$9,"",IFERROR(INDEX($H$13:$H$15,MATCH(C22,$A$13:$A$15,0)),"")) -> 76.513302 | J22: =IF(A22>$B$9,"",IF(OR(G22="",H22="",I22=""),"",G22*4+H22*4+I22*9)) -> 1768 | K22: =IF(OR(A22>$B$9,$B$4=0),"",G22/$B$4) -> 1.7746479 | L22: =IF(OR(A22>$B$9,$B$4=0),"",I22/$B$4) -> 0.90015649 | M22: =IF(A22>$B$9,"未启用",IF(C22="","需设置碳类型",IF(AND(D22<>"是",D22<>"否"),"需设置训练",IF(AND(D22="是",OR(E22="",E22="-")),"请填训练时间",IF(AND(D22="否",E22<>"-"),"休息日时间应为-",IF(I22=0,"脂肪为0：提高热量","正常")))))) -> 正常
A23: 4 | B23: =IF(A23<=$B$9,"第"&A23&"天","未启用") -> 第4天 | C23: 高碳日 | D23: 是 | E23: 晚饭前 | F23: =IF(A23>$B$9,"",IF(D23="是","训练日模板",IF(D23="否","休息日模板","待设置"))) -> 训练日模板 | G23: =IF(A23>$B$9,"",IFERROR(INDEX($F$13:$F$15,MATCH(C23,$A$13:$A$15,0)),"")) -> 268.16901 | H23: =IF(A23>$B$9,"",$B$4*$B$6) -> 119 | I23: =IF(A23>$B$9,"",IFERROR(INDEX($H$13:$H$15,MATCH(C23,$A$13:$A$15,0)),"")) -> 24.369327 | J23: =IF(A23>$B$9,"",IF(OR(G23="",H23="",I23=""),"",G23*4+H23*4+I23*9)) -> 1768 | K23: =IF(OR(A23>$B$9,$B$4=0),"",G23/$B$4) -> 3.1549296 | L23: =IF(OR(A23>$B$9,$B$4=0),"",I23/$B$4) -> 0.28669797 | M23: =IF(A23>$B$9,"未启用",IF(C23="","需设置碳类型",IF(AND(D23<>"是",D23<>"否"),"需设置训练",IF(AND(D23="是",OR(E23="",E23="-")),"请填训练时间",IF(AND(D23="否",E23<>"-"),"休息日时间应为-",IF(I23=0,"脂肪为0：提高热量","正常")))))) -> 正常
A24: 5 | B24: =IF(A24<=$B$9,"第"&A24&"天","未启用") -> 第5天 | C24: 低碳日 | D24: 否 | E24: - | F24: =IF(A24>$B$9,"",IF(D24="是","训练日模板",IF(D24="否","休息日模板","待设置"))) -> 休息日模板 | G24: =IF(A24>$B$9,"",IFERROR(INDEX($F$13:$F$15,MATCH(C24,$A$13:$A$15,0)),"")) -> 100.56338 | H24: =IF(A24>$B$9,"",$B$4*$B$6) -> 119 | I24: =IF(A24>$B$9,"",IFERROR(INDEX($H$13:$H$15,MATCH(C24,$A$13:$A$15,0)),"")) -> 98.86072 | J24: =IF(A24>$B$9,"",IF(OR(G24="",H24="",I24=""),"",G24*4+H24*4+I24*9)) -> 1768 | K24: =IF(OR(A24>$B$9,$B$4=0),"",G24/$B$4) -> 1.1830986 | L24: =IF(OR(A24>$B$9,$B$4=0),"",I24/$B$4) -> 1.1630673 | M24: =IF(A24>$B$9,"未启用",IF(C24="","需设置碳类型",IF(AND(D24<>"是",D24<>"否"),"需设置训练",IF(AND(D24="是",OR(E24="",E24="-")),"请填训练时间",IF(AND(D24="否",E24<>"-"),"休息日时间应为-",IF(I24=0,"脂肪为0：提高热量","正常")))))) -> 正常
A25: 6 | B25: =IF(A25<=$B$9,"第"&A25&"天","未启用") -> 第6天 | C25: 中碳日 | D25: 是 | E25: 晚饭前 | F25: =IF(A25>$B$9,"",IF(D25="是","训练日模板",IF(D25="否","休息日模板","待设置"))) -> 训练日模板 | G25: =IF(A25>$B$9,"",IFERROR(INDEX($F$13:$F$15,MATCH(C25,$A$13:$A$15,0)),"")) -> 150.84507 | H25: =IF(A25>$B$9,"",$B$4*$B$6) -> 119 | I25: =IF(A25>$B$9,"",IFERROR(INDEX($H$13:$H$15,MATCH(C25,$A$13:$A$15,0)),"")) -> 76.513302 | J25: =IF(A25>$B$9,"",IF(OR(G25="",H25="",I25=""),"",G25*4+H25*4+I25*9)) -> 1768 | K25: =IF(OR(A25>$B$9,$B$4=0),"",G25/$B$4) -> 1.7746479 | L25: =IF(OR(A25>$B$9,$B$4=0),"",I25/$B$4) -> 0.90015649 | M25: =IF(A25>$B$9,"未启用",IF(C25="","需设置碳类型",IF(AND(D25<>"是",D25<>"否"),"需设置训练",IF(AND(D25="是",OR(E25="",E25="-")),"请填训练时间",IF(AND(D25="否",E25<>"-"),"休息日时间应为-",IF(I25=0,"脂肪为0：提高热量","正常")))))) -> 正常
A26: 7 | B26: =IF(A26<=$B$9,"第"&A26&"天","未启用") -> 第7天 | C26: 高碳日 | D26: 否 | E26: - | F26: =IF(A26>$B$9,"",IF(D26="是","训练日模板",IF(D26="否","休息日模板","待设置"))) -> 休息日模板 | G26: =IF(A26>$B$9,"",IFERROR(INDEX($F$13:$F$15,MATCH(C26,$A$13:$A$15,0)),"")) -> 268.16901 | H26: =IF(A26>$B$9,"",$B$4*$B$6) -> 119 | I26: =IF(A26>$B$9,"",IFERROR(INDEX($H$13:$H$15,MATCH(C26,$A$13:$A$15,0)),"")) -> 24.369327 | J26: =IF(A26>$B$9,"",IF(OR(G26="",H26="",I26=""),"",G26*4+H26*4+I26*9)) -> 1768 | K26: =IF(OR(A26>$B$9,$B$4=0),"",G26/$B$4) -> 3.1549296 | L26: =IF(OR(A26>$B$9,$B$4=0),"",I26/$B$4) -> 0.28669797 | M26: =IF(A26>$B$9,"未启用",IF(C26="","需设置碳类型",IF(AND(D26<>"是",D26<>"否"),"需设置训练",IF(AND(D26="是",OR(E26="",E26="-")),"请填训练时间",IF(AND(D26="否",E26<>"-"),"休息日时间应为-",IF(I26=0,"脂肪为0：提高热量","正常")))))) -> 正常
A27: 8 | B27: =IF(A27<=$B$9,"第"&A27&"天","未启用") -> 未启用 | C27: 中碳日 | D27: 是 | E27: 晚饭前 | F27: =IF(A27>$B$9,"",IF(D27="是","训练日模板",IF(D27="否","休息日模板","待设置"))) | G27: =IF(A27>$B$9,"",IFERROR(INDEX($F$13:$F$15,MATCH(C27,$A$13:$A$15,0)),"")) | H27: =IF(A27>$B$9,"",$B$4*$B$6) | I27: =IF(A27>$B$9,"",IFERROR(INDEX($H$13:$H$15,MATCH(C27,$A$13:$A$15,0)),"")) | J27: =IF(A27>$B$9,"",IF(OR(G27="",H27="",I27=""),"",G27*4+H27*4+I27*9)) | K27: =IF(OR(A27>$B$9,$B$4=0),"",G27/$B$4) | L27: =IF(OR(A27>$B$9,$B$4=0),"",I27/$B$4) | M27: =IF(A27>$B$9,"未启用",IF(C27="","需设置碳类型",IF(AND(D27<>"是",D27<>"否"),"需设置训练",IF(AND(D27="是",OR(E27="",E27="-")),"请填训练时间",IF(AND(D27="否",E27<>"-"),"休息日时间应为-",IF(I27=0,"脂肪为0：提高热量","正常")))))) -> 未启用
A28: 9 | B28: =IF(A28<=$B$9,"第"&A28&"天","未启用") -> 未启用 | C28: 低碳日 | D28: 否 | E28: - | F28: =IF(A28>$B$9,"",IF(D28="是","训练日模板",IF(D28="否","休息日模板","待设置"))) | G28: =IF(A28>$B$9,"",IFERROR(INDEX($F$13:$F$15,MATCH(C28,$A$13:$A$15,0)),"")) | H28: =IF(A28>$B$9,"",$B$4*$B$6) | I28: =IF(A28>$B$9,"",IFERROR(INDEX($H$13:$H$15,MATCH(C28,$A$13:$A$15,0)),"")) | J28: =IF(A28>$B$9,"",IF(OR(G28="",H28="",I28=""),"",G28*4+H28*4+I28*9)) | K28: =IF(OR(A28>$B$9,$B$4=0),"",G28/$B$4) | L28: =IF(OR(A28>$B$9,$B$4=0),"",I28/$B$4) | M28: =IF(A28>$B$9,"未启用",IF(C28="","需设置碳类型",IF(AND(D28<>"是",D28<>"否"),"需设置训练",IF(AND(D28="是",OR(E28="",E28="-")),"请填训练时间",IF(AND(D28="否",E28<>"-"),"休息日时间应为-",IF(I28=0,"脂肪为0：提高热量","正常")))))) -> 未启用
A29: 10 | B29: =IF(A29<=$B$9,"第"&A29&"天","未启用") -> 未启用 | C29: 中碳日 | D29: 是 | E29: 晚饭前 | F29: =IF(A29>$B$9,"",IF(D29="是","训练日模板",IF(D29="否","休息日模板","待设置"))) | G29: =IF(A29>$B$9,"",IFERROR(INDEX($F$13:$F$15,MATCH(C29,$A$13:$A$15,0)),"")) | H29: =IF(A29>$B$9,"",$B$4*$B$6) | I29: =IF(A29>$B$9,"",IFERROR(INDEX($H$13:$H$15,MATCH(C29,$A$13:$A$15,0)),"")) | J29: =IF(A29>$B$9,"",IF(OR(G29="",H29="",I29=""),"",G29*4+H29*4+I29*9)) | K29: =IF(OR(A29>$B$9,$B$4=0),"",G29/$B$4) | L29: =IF(OR(A29>$B$9,$B$4=0),"",I29/$B$4) | M29: =IF(A29>$B$9,"未启用",IF(C29="","需设置碳类型",IF(AND(D29<>"是",D29<>"否"),"需设置训练",IF(AND(D29="是",OR(E29="",E29="-")),"请填训练时间",IF(AND(D29="否",E29<>"-"),"休息日时间应为-",IF(I29=0,"脂肪为0：提高热量","正常")))))) -> 未启用
A30: 11 | B30: =IF(A30<=$B$9,"第"&A30&"天","未启用") -> 未启用 | C30: 高碳日 | D30: 是 | E30: 晚饭前 | F30: =IF(A30>$B$9,"",IF(D30="是","训练日模板",IF(D30="否","休息日模板","待设置"))) | G30: =IF(A30>$B$9,"",IFERROR(INDEX($F$13:$F$15,MATCH(C30,$A$13:$A$15,0)),"")) | H30: =IF(A30>$B$9,"",$B$4*$B$6) | I30: =IF(A30>$B$9,"",IFERROR(INDEX($H$13:$H$15,MATCH(C30,$A$13:$A$15,0)),"")) | J30: =IF(A30>$B$9,"",IF(OR(G30="",H30="",I30=""),"",G30*4+H30*4+I30*9)) | K30: =IF(OR(A30>$B$9,$B$4=0),"",G30/$B$4) | L30: =IF(OR(A30>$B$9,$B$4=0),"",I30/$B$4) | M30: =IF(A30>$B$9,"未启用",IF(C30="","需设置碳类型",IF(AND(D30<>"是",D30<>"否"),"需设置训练",IF(AND(D30="是",OR(E30="",E30="-")),"请填训练时间",IF(AND(D30="否",E30<>"-"),"休息日时间应为-",IF(I30=0,"脂肪为0：提高热量","正常")))))) -> 未启用
A31: 12 | B31: =IF(A31<=$B$9,"第"&A31&"天","未启用") -> 未启用 | C31: 低碳日 | D31: 否 | E31: - | F31: =IF(A31>$B$9,"",IF(D31="是","训练日模板",IF(D31="否","休息日模板","待设置"))) | G31: =IF(A31>$B$9,"",IFERROR(INDEX($F$13:$F$15,MATCH(C31,$A$13:$A$15,0)),"")) | H31: =IF(A31>$B$9,"",$B$4*$B$6) | I31: =IF(A31>$B$9,"",IFERROR(INDEX($H$13:$H$15,MATCH(C31,$A$13:$A$15,0)),"")) | J31: =IF(A31>$B$9,"",IF(OR(G31="",H31="",I31=""),"",G31*4+H31*4+I31*9)) | K31: =IF(OR(A31>$B$9,$B$4=0),"",G31/$B$4) | L31: =IF(OR(A31>$B$9,$B$4=0),"",I31/$B$4) | M31: =IF(A31>$B$9,"未启用",IF(C31="","需设置碳类型",IF(AND(D31<>"是",D31<>"否"),"需设置训练",IF(AND(D31="是",OR(E31="",E31="-")),"请填训练时间",IF(AND(D31="否",E31<>"-"),"休息日时间应为-",IF(I31=0,"脂肪为0：提高热量","正常")))))) -> 未启用
... A50: 31 | B50: =IF(A50<=$B$9,"第"&A50&"天","未启用") -> 未启用 | C50: 中碳日 | D50: 是 | E50: 晚饭前 | F50: =IF(A50>$B$9,"",IF(D50="是","训练日模板",IF(D50="否","休息日模板","待设置"))) | G50: =IF(A50>$B$9,"",IFERROR(INDEX($F$13:$F$15,MATCH(C50,$A$13:$A$15,0)),"")) | H50: =IF(A50>$B$9,"",$B$4*$B$6) | I50: =IF(A50>$B$9,"",IFERROR(INDEX($H$13:$H$15,MATCH(C50,$A$13:$A$15,0)),"")) | J50: =IF(A50>$B$9,"",IF(OR(G50="",H50="",I50=""),"",G50*4+H50*4+I50*9)) | K50: =IF(OR(A50>$B$9,$B$4=0),"",G50/$B$4) | L50: =IF(OR(A50>$B$9,$B$4=0),"",I50/$B$4) | M50: =IF(A50>$B$9,"未启用",IF(C50="","需设置碳类型",IF(AND(D50<>"是",D50<>"否"),"需设置训练",IF(AND(D50="是",OR(E50="",E50="-")),"请填训练时间",IF(AND(D50="否",E50<>"-"),"休息日时间应为-",IF(I50=0,"脂肪为0：提高热量","正常")))))) -> 未启用
A51: 周期合计 | B51: =COUNTIF(B20:B50,"<>未启用") -> 7 | G51: =SUM(G20:G50) -> 1190 | H51: =SUM(H20:H50) -> 833 | I51: =SUM(I20:I50) -> 476 | J51: =SUM(J20:J50) -> 12376 | M51: =IF(COUNTIFS($A$20:$A$50,"<="&$B$9,$M$20:$M$50,"<>正常")=0,"全部正常","请检查提示") -> 全部正常
A53: 使用方法：先在B9设置循环长度，再逐日调整C～E列；周期可以是7、10、14、21或其他1～31天长度。
A54: 碳水总量按“体重 × 基础碳水 × 循环长度”计算；默认高/中/低权重为1.60/0.90/0.60，并依据实际天数自动归一化，因此改变周期长度也不会丢失或重复分配碳水。
A55: 训练日自动套用含纯碳水练前餐的模板，休息日自动取消练前餐。完整分餐目标请查看“V6周期饮食总览”，克数请查看“V6智能饮食计划”。

Sheet V6设置
A1: 碳循环减脂 V6｜循环联动与餐食分配设置
A3: ① 循环与饮食联动（循环日在“V6周期计划”设置）
A4: 当前循环长度（天） | B4: =V6周期计划!$B$9 -> 7 | C4: 训练日数量 | D4: =COUNTIFS(V6周期计划!$A$20:$A$50,"<="&V6周期计划!$B$9,V6周期计划!$D$20:$D$50,"是") -> 4 | E4: 休息日数量 | F4: =COUNTIFS(V6周期计划!$A$20:$A$50,"<="&V6周期计划!$B$9,V6周期计划!$D$20:$D$50,"否") -> 3
A6: • 每个循环日独立设置高/中/低碳、是否训练及训练时间；修改循环长度后，只有启用的循环日参与计算。
A7: • 训练日自动使用下方训练日模板，并安排纯碳水练前餐；休息日自动使用休息日模板且取消练前餐。
A8: • 高/中/低碳默认权重1.60/0.90/0.60并按实际天数自动归一化；分餐比例按营养素分别分配，三列均应各自合计100%。
A13: ② 训练日餐食分配（练前餐为纯碳水；晚饭/练后餐碳水固定40%）
A14: 餐次 | B14: 碳水比例 | C14: 蛋白质比例 | D14: 脂肪比例 | E14: 备注
A15: 早餐 | B15: 0.25 | C15: 0.2 | D15: 0.2 | E15: 正常早餐
A16: 午餐 | B16: 0.25 | C16: 0.4 | D16: 0.4 | E16: 下午训练前保持饱腹
A17: 练前餐 | B17: 0.1 | C17: 0 | D17: 0 | E17: 纯碳水餐：训练前60~90分钟，只安排易消化主食
A18: 晚饭/练后餐 | B18: 0.4 | C18: 0.4 | D18: 0.4 | E18: 训练后重点补充；承接练前餐移出的蛋白质/脂肪
A19: 合计 | B19: =SUM(B15:B18) -> 1 | C19: =SUM(C15:C18) -> 1 | D19: =SUM(D15:D18) -> 1
A21: ③ 休息日餐食分配（练前餐自动取消）
A22: 餐次 | B22: 碳水比例 | C22: 蛋白质比例 | D22: 脂肪比例 | E22: 备注
A23: 早餐 | B23: 0.3 | C23: 0.3 | D23: 0.3 | E23: 正常
A24: 午餐 | B24: 0.4 | C24: 0.4 | D24: 0.4 | E24: 当天主餐
A25: 练前餐 | B25: 0 | C25: 0 | D25: 0 | E25: 休息日不需要，可留空
A26: 晚饭 | B26: 0.3 | C26: 0.3 | D26: 0.3 | E26: 正常
A27: 合计 | B27: =SUM(B23:B26) -> 1 | C27: =SUM(C23:C26) -> 1 | D27: =SUM(D23:D26) -> 1
A29: ④ V6 精确配餐与周期联动逻辑
A30: 1）智能配餐以当前选择的循环日为入口，同时读取该日碳类型、训练状态、训练时间和三大营养素目标；
A31: 2）非练前餐联立主食、蛋白食物、脂肪食物的营养矩阵；异常时自动回退到碳水→蛋白质→脂肪顺序残差；
A32: 3）训练日练前餐只安排易消化主食；休息日练前餐为0，其他三餐按休息日比例分配；
A33: 4）营养计算使用数据库口径，显示克数再依据“熟重÷生重系数”转换；换算不会重复计算营养；
A34: 5）“V6周期饮食总览”显示整个循环每一天、每一餐的营养目标；“V6智能饮食计划”用于查看单日食物克数。

Sheet V6智能饮食计划
A1: 碳循环减脂 V6.4｜按循环日智能配餐＋主选候补同列
A3: ① 选择循环日（自动联动碳类型、训练状态与餐食模板）
A4: 选择循环日 | B4: 1 | D4: 是否训练 | E4: =IFERROR(VLOOKUP(B4,V6周期计划!$A$20:$M$50,4,FALSE),"") -> 是 | G4: 碳循环类型 | H4: =IFERROR(VLOOKUP(B4,V6周期计划!$A$20:$M$50,3,FALSE),"") -> 中碳日 | J4: 碳水目标(g) | K4: =IF(B4>CycleLength,"",IFERROR(VLOOKUP(B4,V6周期计划!$A$20:$M$50,7,FALSE),"")) -> 150.84507 | M4: 蛋白质目标(g) | N4: =IF(B4>CycleLength,"",IFERROR(VLOOKUP(B4,V6周期计划!$A$20:$M$50,8,FALSE),"")) -> 119 | P4: 脂肪目标(g) | Q4: =IF(B4>CycleLength,"",IFERROR(VLOOKUP(B4,V6周期计划!$A$20:$M$50,9,FALSE),"")) -> 76.513302 | S4: 热量目标(kcal) | T4: =IF(B4>CycleLength,"",IFERROR(VLOOKUP(B4,V6周期计划!$A$20:$M$50,10,FALSE),"")) -> 1768
A5: 周期长度 | B5: =CycleLength -> 7 | D5: 训练时间 | E5: =IFERROR(VLOOKUP(B4,V6周期计划!$A$20:$M$50,5,FALSE),"") -> 晚饭前 | G5: 餐食模板 | H5: =IFERROR(VLOOKUP(B4,V6周期计划!$A$20:$M$50,6,FALSE),"") -> 训练日模板 | J5: 循环日状态 | K5: =IF(B4>CycleLength,"未启用",IFERROR(VLOOKUP(B4,V6周期计划!$A$20:$M$50,13,FALSE),"请检查")) -> 正常 | M5: 选择提示 | N5: =IF(B4<=CycleLength,"已启用；修改B4查看其他循环日","超出当前循环长度") -> 已启用；修改B4查看其他循环日
A6: ② 餐食比例（按当前循环日自动切换训练/休息模板）
A7: 餐次 | B7: 碳水比例 | C7: 蛋白质比例 | D7: 脂肪比例 | E7: 餐食状态
A8: 早餐 | B8: =IF($E$4="是",V6设置!B15,V6设置!B23) -> 0.25 | C8: =IF($E$4="是",V6设置!C15,V6设置!C23) -> 0.2 | D8: =IF($E$4="是",V6设置!D15,V6设置!D23) -> 0.2 | E8: =IF(AND($E$4="否",A8="练前餐"),"休息日不安排",IF(A8="练前餐","纯碳水","执行")) -> 执行
A9: 午餐 | B9: =IF($E$4="是",V6设置!B16,V6设置!B24) -> 0.25 | C9: =IF($E$4="是",V6设置!C16,V6设置!C24) -> 0.4 | D9: =IF($E$4="是",V6设置!D16,V6设置!D24) -> 0.4 | E9: =IF(AND($E$4="否",A9="练前餐"),"休息日不安排",IF(A9="练前餐","纯碳水","执行")) -> 执行
A10: 练前餐 | B10: =IF($E$4="是",V6设置!B17,V6设置!B25) -> 0.1 | C10: =IF($E$4="是",V6设置!C17,V6设置!C25) -> 0 | D10: =IF($E$4="是",V6设置!D17,V6设置!D25) -> 0 | E10: =IF(AND($E$4="否",A10="练前餐"),"休息日不安排",IF(A10="练前餐","纯碳水","执行")) -> 纯碳水
A11: 晚饭/练后餐 | B11: =IF($E$4="是",V6设置!B18,V6设置!B26) -> 0.4 | C11: =IF($E$4="是",V6设置!C18,V6设置!C26) -> 0.4 | D11: =IF($E$4="是",V6设置!D18,V6设置!D26) -> 0.4 | E11: =IF(AND($E$4="否",A11="练前餐"),"休息日不安排",IF(A11="练前餐","纯碳水","执行")) -> 执行
A13: ③ 智能配餐（每餐主选与候补同列对照）
A14: 餐次 | B14: 方案 | C14: 碳水% | D14: 蛋白% | E14: 脂肪% | F14: 主食选择 | G14: 主食口径 | H14: 主食克数 | I14: 蛋白选择 | J14: 蛋白口径 | K14: 蛋白克数 | L14: 脂肪选择 | M14: 脂肪克数 | N14: 蔬菜选择 | O14: 蔬菜克数 | P14: 本餐碳水 | Q14: 本餐蛋白 | R14: 本餐脂肪 | S14: 本餐热量 | T14: 求解模式
A15: 早餐 | B15: 主选 | C15: =B8 -> 0.25 | D15: =C8 -> 0.2 | E15: =D8 -> 0.2 | F15: 土豆（熟） | G15: 熟重 | H15: =G50 -> 165.3604 | I15: 鸡蛋 | J15: 生重 | K15: =J50 -> 155.49835 | L15: 橄榄油 | M15: =L50 -> 0 | N15: 胡萝卜 | O15: 100 | P15: =O50 -> 39.421749 | Q15: =P50 -> 23.8 | R15: =Q50 -> 15.915195 | S15: =R50 -> 396.12376 | T15: =S50 -> 顺序
B16: 候补1 | F16: 燕麦（干） | G16: =IF(F16="-","-",IFERROR(VLOOKUP(F16,食物数据库V3!$B$6:$K$59,8,FALSE),"-")) -> 生重 | H16: =C60 -> 42.400102 | I16: 脱脂牛奶 | J16: =IF(I16="-","-",IFERROR(VLOOKUP(I16,食物数据库V3!$B$6:$K$59,8,FALSE),"-")) -> 熟重 | K16: =I60 -> 576.25859 | L16: 腰果 | M16: =O60 -> 0
B17: 候补2 | F17: 全麦面包 | G17: =IF(F17="-","-",IFERROR(VLOOKUP(F17,食物数据库V3!$B$6:$K$59,8,FALSE),"-")) -> 熟重 | H17: =E60 -> 73.97702 | I17: 希腊酸奶（低脂） | J17: =IF(I17="-","-",IFERROR(VLOOKUP(I17,食物数据库V3!$B$6:$K$59,8,FALSE),"-")) -> 熟重 | K17: =K60 -> 195.92792 | L17: 杏仁 | M17: =Q60 -> 0
B18: 候补3 | F18: 熟米饭 | G18: =IF(F18="-","-",IFERROR(VLOOKUP(F18,食物数据库V3!$B$6:$K$59,8,FALSE),"-")) -> 熟重 | H18: =G60 -> 93.704225 | J18: =IF(I18="-","-",IFERROR(VLOOKUP(I18,食物数据库V3!$B$6:$K$59,8,FALSE),"-")) -> - | K18: =M60 -> 0 | L18: 花生酱 | M18: =S60 -> 0
A19: 午餐 | B19: 主选 | C19: =B9 -> 0.25 | D19: =C9 -> 0.4 | E19: =D9 -> 0.4 | F19: 熟米饭 | G19: 熟重 | H19: =G51 -> 79.037559 | I19: 鸡胸肉（生） | J19: 生重 | K19: =J51 -> 181.56829 | L19: 橄榄油 | M19: =L51 -> 26.844684 | N19: 西兰花 | O19: 200 | P19: =O51 -> 37.711268 | Q19: =P51 -> 47.6 | R19: =Q51 -> 30.605321 | S19: =R51 -> 616.69296 | T19: =S51 -> 精确
B20: 候补1 | F20: 熟米饭 | G20: =IF(F20="-","-",IFERROR(VLOOKUP(F20,食物数据库V3!$B$6:$K$59,8,FALSE),"-")) -> 熟重 | H20: =C61 -> 79.037559 | I20: 鸡胸肉（生） | J20: =IF(I20="-","-",IFERROR(VLOOKUP(I20,食物数据库V3!$B$6:$K$59,8,FALSE),"-")) -> 生重 | K20: =I61 -> 181.56829 | L20: 橄榄油 | M20: =O61 -> 26.844684
B21: 候补2 | F21: 土豆（熟） | G21: =IF(F21="-","-",IFERROR(VLOOKUP(F21,食物数据库V3!$B$6:$K$59,8,FALSE),"-")) -> 熟重 | H21: =E61 -> 139.47804 | I21: 虾仁 | J21: =IF(I21="-","-",IFERROR(VLOOKUP(I21,食物数据库V3!$B$6:$K$59,8,FALSE),"-")) -> 生重 | K21: =K61 -> 199.72512 | L21: 腰果 | M21: =Q61 -> 61.289232
B22: 候补3 | F22: 红薯（熟） | G22: =IF(F22="-","-",IFERROR(VLOOKUP(F22,食物数据库V3!$B$6:$K$59,8,FALSE),"-")) -> 熟重 | H22: =G61 -> 117.96651 | I22: 金枪鱼（水浸） | J22: =IF(I22="-","-",IFERROR(VLOOKUP(I22,食物数据库V3!$B$6:$K$59,8,FALSE),"-")) -> 熟重 | K22: =M61 -> 153.63471 | L22: 牛油果 | M22: =S61 -> 182.6169
A23: 练前餐 | B23: 主选 | C23: =B10 -> 0.1 | D23: =C10 -> 0 | E23: =D10 -> 0 | F23: 红薯（熟） | G23: 熟重 | H23: =G52 -> 75.047299 | I23: - | J23: - | K23: =J52 -> 0 | L23: - | M23: =L52 -> 0 | N23: - | O23: 0 | P23: =O52 -> 15.084507 | Q23: =P52 -> 1.2007568 | R23: =Q52 -> 0.075047299 | S23: =R52 -> 65.816481 | T23: =S52 -> 纯碳水
B24: 候补1 | F24: 红薯（熟） | G24: =IF(F24="-","-",IFERROR(VLOOKUP(F24,食物数据库V3!$B$6:$K$59,8,FALSE),"-")) -> 熟重 | H24: =C62 -> 75.047299 | I24: - | J24: =IF(I24="-","-",IFERROR(VLOOKUP(I24,食物数据库V3!$B$6:$K$59,8,FALSE),"-")) -> - | K24: =I62 -> 0 | L24: - | M24: =O62 -> 0
B25: 候补2 | F25: 土豆（熟） | G25: =IF(F25="-","-",IFERROR(VLOOKUP(F25,食物数据库V3!$B$6:$K$59,8,FALSE),"-")) -> 熟重 | H25: =E62 -> 88.732394 | I25: - | J25: =IF(I25="-","-",IFERROR(VLOOKUP(I25,食物数据库V3!$B$6:$K$59,8,FALSE),"-")) -> - | K25: =K62 -> 0 | L25: - | M25: =Q62 -> 0
B26: 候补3 | F26: 熟米饭 | G26: =IF(F26="-","-",IFERROR(VLOOKUP(F26,食物数据库V3!$B$6:$K$59,8,FALSE),"-")) -> 熟重 | H26: =G62 -> 50.28169 | I26: - | J26: =IF(I26="-","-",IFERROR(VLOOKUP(I26,食物数据库V3!$B$6:$K$59,8,FALSE),"-")) -> - | K26: =M62 -> 0 | L26: - | M26: =S62 -> 0
A27: 晚饭/练后餐 | B27: 主选 | C27: =B11 -> 0.4 | D27: =C11 -> 0.4 | E27: =D11 -> 0.4 | F27: 荞麦面（熟） | G27: 熟重 | H27: =G53 -> 152.36307 | I27: 鸡胸肉（生） | J27: 生重 | K27: =J53 -> 172.86129 | L27: 橄榄油 | M27: =L53 -> 27.460038 | N27: 胡萝卜 | O27: 200 | P27: =O53 -> 60.338028 | Q27: =P53 -> 47.6 | R27: =Q53 -> 30.605321 | S27: =R53 -> 707.2 | T27: =S53 -> 精确
B28: 候补1 | F28: 荞麦面（熟） | G28: =IF(F28="-","-",IFERROR(VLOOKUP(F28,食物数据库V3!$B$6:$K$59,8,FALSE),"-")) -> 熟重 | H28: =C63 -> 152.36307 | I28: 鸡胸肉（生） | J28: =IF(I28="-","-",IFERROR(VLOOKUP(I28,食物数据库V3!$B$6:$K$59,8,FALSE),"-")) -> 生重 | K28: =I63 -> 172.86129 | L28: 橄榄油 | M28: =O63 -> 27.460038
B29: 候补2 | F29: 熟米饭 | G29: =IF(F29="-","-",IFERROR(VLOOKUP(F29,食物数据库V3!$B$6:$K$59,8,FALSE),"-")) -> 熟重 | H29: =E63 -> 137.12676 | I29: 虾仁 | J29: =IF(I29="-","-",IFERROR(VLOOKUP(I29,食物数据库V3!$B$6:$K$59,8,FALSE),"-")) -> 生重 | K29: =K63 -> 190.14742 | L29: 腰果 | M29: =Q63 -> 62.694152
B30: 候补3 | F30: 红薯（熟） | G30: =IF(F30="-","-",IFERROR(VLOOKUP(F30,食物数据库V3!$B$6:$K$59,8,FALSE),"-")) -> 熟重 | H30: =G63 -> 204.66681 | I30: 金枪鱼（水浸） | J30: =IF(I30="-","-",IFERROR(VLOOKUP(I30,食物数据库V3!$B$6:$K$59,8,FALSE),"-")) -> 熟重 | K30: =M63 -> 146.26724 | L30: 花生酱 | M30: =S63 -> 54.920077
A32: ④ 全天实际摄入 vs 当天目标
A33: 项目 | B33: 目标 | C33: 实际 | D33: 差异（实际-目标）
A34: 碳水(g) | B34: =$K$4 -> 150.84507 | C34: =SUM(P15,P19,P23,P27) -> 152.55555 | D34: =C34-B34 -> 1.7104818
A35: 蛋白质(g) | B35: =$N$4 -> 119 | C35: =SUM(Q15,Q19,Q23,Q27) -> 120.20076 | D35: =C35-B35 -> 1.2007568
A36: 脂肪(g) | B36: =$Q$4 -> 76.513302 | C36: =SUM(R15,R19,R23,R27) -> 77.200884 | D36: =C36-B36 -> 0.68758225
A37: 热量(kcal) | B37: =$T$4 -> 1768 | C37: =SUM(S15,S19,S23,S27) -> 1785.8332 | D37: =C37-B37 -> 17.833195
A39: ⑤ 使用提示
A40: • 在B4选择循环日编号；碳类型、训练状态、训练时间、营养目标和餐食模板均自动来自“V6周期计划”。
A41: • 每个餐次按“主选、候补1、候补2、候补3”纵向排列；候补食物与主选位于相同列，便于直接比较。
A42: • 候补为主食、蛋白质、脂肪的单项等效替换，不代表候补1三种食物必须同时组成一整餐。
A43: • 训练日练前餐是纯碳水餐，只选择主食；休息日练前餐自动为0。主食天然携带的少量蛋白质/脂肪仍计入实际。
A44: • 主食口径与蛋白口径可选择“生重/熟重”；换算只改变建议称量克数，不改变同一份食物对应的营养素。
...

Sheet V6自由组合饮食计划
A1: 碳循环减脂 V6.8｜自由组合饮食计划（每餐最多6种食物）
A3: ① 选择循环日（完整目标信息已收拢到本页可视宽度内）
A4: 选择循环日 | B4: 1 | C4: 是否训练 | D4: =IFERROR(VLOOKUP(B4,V6周期计划!$A$20:$M$50,4,FALSE),"") -> 是 | E4: 碳循环类型 | F4: =IFERROR(VLOOKUP(B4,V6周期计划!$A$20:$M$50,3,FALSE),"") -> 中碳日 | G4: 碳水目标(g) | H4: =IF(B4>CycleLength,"",IFERROR(VLOOKUP(B4,V6周期计划!$A$20:$M$50,7,FALSE),"")) -> 150.84507 | I4: 蛋白质目标(g) | J4: =IF(B4>CycleLength,"",IFERROR(VLOOKUP(B4,V6周期计划!$A$20:$M$50,8,FALSE),"")) -> 119 | K4: 脂肪目标(g) | L4: =IF(B4>CycleLength,"",IFERROR(VLOOKUP(B4,V6周期计划!$A$20:$M$50,9,FALSE),"")) -> 76.513302
A5: 周期长度 | B5: =CycleLength -> 7 | C5: 训练时间 | D5: =IFERROR(VLOOKUP(B4,V6周期计划!$A$20:$M$50,5,FALSE),"") -> 晚饭前 | E5: 餐食模板 | F5: =IFERROR(VLOOKUP(B4,V6周期计划!$A$20:$M$50,6,FALSE),"") -> 训练日模板 | G5: 热量目标(kcal) | H5: =IF(B4>CycleLength,"",IFERROR(VLOOKUP(B4,V6周期计划!$A$20:$M$50,10,FALSE),"")) -> 1768 | I5: 循环日状态 | J5: =IF(B4>CycleLength,"未启用",IFERROR(VLOOKUP(B4,V6周期计划!$A$20:$M$50,13,FALSE),"请检查")) -> 正常 | K5: 选择提示 | L5: =IF(B4<=CycleLength,"已启用；自由组合","超出循环长度") -> 已启用；自由组合
A6: ② 自由组合配餐（黄色区域可修改；每餐最多6种食物）
A7: 餐次 | B7: 序号 | C7: 类别 | D7: 食物选择 | E7: 称重口径 | F7: 输入重量(g) | G7: 营养基准重量(g) | H7: 碳水(g) | I7: 蛋白质(g) | J7: 脂肪(g) | K7: 热量(kcal)
A8: 早餐 | B8: 1 | C8: 主食 | D8: 土豆（熟） | E8: =IF(D8="","",IFERROR(VLOOKUP(D8,食物数据库V3!$B$6:$K$59,8,FALSE),"")) -> 熟重 | F8: 150 | G8: =IF(OR(D8="",F8=""),0,IFERROR(F8*IF(OR(VLOOKUP(D8,食物数据库V3!$B$6:$K$59,7,FALSE)="无需换算",E8=VLOOKUP(D8,食物数据库V3!$B$6:$K$59,7,FALSE)),1,IF(E8="熟重",1/VLOOKUP(D8,食物数据库V3!$B$6:$K$59,9,FALSE),VLOOKUP(D8,食物数据库V3!$B$6:$K$59,9,FALSE))),0)) -> 150 | H8: =IFERROR(G8*VLOOKUP(D8,食物数据库V3!$B$6:$K$59,2,FALSE)/100,0) -> 25.5 | I8: =IFERROR(G8*VLOOKUP(D8,食物数据库V3!$B$6:$K$59,3,FALSE)/100,0) -> 3 | J8: =IFERROR(G8*VLOOKUP(D8,食物数据库V3!$B$6:$K$59,4,FALSE)/100,0) -> 0.15 | K8: =IFERROR(G8*VLOOKUP(D8,食物数据库V3!$B$6:$K$59,5,FALSE)/100,0) -> 115.5
A9: 早餐 | B9: 2 | C9: 蛋白质 | D9: 鸡蛋 | E9: =IF(D9="","",IFERROR(VLOOKUP(D9,食物数据库V3!$B$6:$K$59,8,FALSE),"")) -> 熟重 | F9: 120 | G9: =IF(OR(D9="",F9=""),0,IFERROR(F9*IF(OR(VLOOKUP(D9,食物数据库V3!$B$6:$K$59,7,FALSE)="无需换算",E9=VLOOKUP(D9,食物数据库V3!$B$6:$K$59,7,FALSE)),1,IF(E9="熟重",1/VLOOKUP(D9,食物数据库V3!$B$6:$K$59,9,FALSE),VLOOKUP(D9,食物数据库V3!$B$6:$K$59,9,FALSE))),0)) -> 120 | H9: =IFERROR(G9*VLOOKUP(D9,食物数据库V3!$B$6:$K$59,2,FALSE)/100,0) -> 1.32 | I9: =IFERROR(G9*VLOOKUP(D9,食物数据库V3!$B$6:$K$59,3,FALSE)/100,0) -> 15.12 | J9: =IFERROR(G9*VLOOKUP(D9,食物数据库V3!$B$6:$K$59,4,FALSE)/100,0) -> 12 | K9: =IFERROR(G9*VLOOKUP(D9,食物数据库V3!$B$6:$K$59,5,FALSE)/100,0) -> 174
A10: 早餐 | B10: 3 | C10: 蛋白质 | D10: 全脂牛奶 | E10: =IF(D10="","",IFERROR(VLOOKUP(D10,食物数据库V3!$B$6:$K$59,8,FALSE),"")) -> 熟重 | F10: 200 | G10: =IF(OR(D10="",F10=""),0,IFERROR(F10*IF(OR(VLOOKUP(D10,食物数据库V3!$B$6:$K$59,7,FALSE)="无需换算",E10=VLOOKUP(D10,食物数据库V3!$B$6:$K$59,7,FALSE)),1,IF(E10="熟重",1/VLOOKUP(D10,食物数据库V3!$B$6:$K$59,9,FALSE),VLOOKUP(D10,食物数据库V3!$B$6:$K$59,9,FALSE))),0)) -> 200 | H10: =IFERROR(G10*VLOOKUP(D10,食物数据库V3!$B$6:$K$59,2,FALSE)/100,0) -> 9 | I10: =IFERROR(G10*VLOOKUP(D10,食物数据库V3!$B$6:$K$59,3,FALSE)/100,0) -> 7 | J10: =IFERROR(G10*VLOOKUP(D10,食物数据库V3!$B$6:$K$59,4,FALSE)/100,0) -> 7 | K10: =IFERROR(G10*VLOOKUP(D10,食物数据库V3!$B$6:$K$59,5,FALSE)/100,0) -> 128
A11: 早餐 | B11: 4 | C11: 脂肪 | E11: =IF(D11="","",IFERROR(VLOOKUP(D11,食物数据库V3!$B$6:$K$59,8,FALSE),"")) | F11: 10 | G11: =IF(OR(D11="",F11=""),0,IFERROR(F11*IF(OR(VLOOKUP(D11,食物数据库V3!$B$6:$K$59,7,FALSE)="无需换算",E11=VLOOKUP(D11,食物数据库V3!$B$6:$K$59,7,FALSE)),1,IF(E11="熟重",1/VLOOKUP(D11,食物数据库V3!$B$6:$K$59,9,FALSE),VLOOKUP(D11,食物数据库V3!$B$6:$K$59,9,FALSE))),0)) -> 0 | H11: =IFERROR(G11*VLOOKUP(D11,食物数据库V3!$B$6:$K$59,2,FALSE)/100,0) -> 0 | I11: =IFERROR(G11*VLOOKUP(D11,食物数据库V3!$B$6:$K$59,3,FALSE)/100,0) -> 0 | J11: =IFERROR(G11*VLOOKUP(D11,食物数据库V3!$B$6:$K$59,4,FALSE)/100,0) -> 0 | K11: =IFERROR(G11*VLOOKUP(D11,食物数据库V3!$B$6:$K$59,5,FALSE)/100,0) -> 0
A12: 早餐 | B12: 5 | C12: 蔬菜 | E12: =IF(D12="","",IFERROR(VLOOKUP(D12,食物数据库V3!$B$6:$K$59,8,FALSE),"")) | F12: 100 | G12: =IF(OR(D12="",F12=""),0,IFERROR(F12*IF(OR(VLOOKUP(D12,食物数据库V3!$B$6:$K$59,7,FALSE)="无需换算",E12=VLOOKUP(D12,食物数据库V3!$B$6:$K$59,7,FALSE)),1,IF(E12="熟重",1/VLOOKUP(D12,食物数据库V3!$B$6:$K$59,9,FALSE),VLOOKUP(D12,食物数据库V3!$B$6:$K$59,9,FALSE))),0)) -> 0 | H12: =IFERROR(G12*VLOOKUP(D12,食物数据库V3!$B$6:$K$59,2,FALSE)/100,0) -> 0 | I12: =IFERROR(G12*VLOOKUP(D12,食物数据库V3!$B$6:$K$59,3,FALSE)/100,0) -> 0 | J12: =IFERROR(G12*VLOOKUP(D12,食物数据库V3!$B$6:$K$59,4,FALSE)/100,0) -> 0 | K12: =IFERROR(G12*VLOOKUP(D12,食物数据库V3!$B$6:$K$59,5,FALSE)/100,0) -> 0
A13: 早餐 | B13: 6 | E13: =IF(D13="","",IFERROR(VLOOKUP(D13,食物数据库V3!$B$6:$K$59,8,FALSE),"")) | G13: =IF(OR(D13="",F13=""),0,IFERROR(F13*IF(OR(VLOOKUP(D13,食物数据库V3!$B$6:$K$59,7,FALSE)="无需换算",E13=VLOOKUP(D13,食物数据库V3!$B$6:$K$59,7,FALSE)),1,IF(E13="熟重",1/VLOOKUP(D13,食物数据库V3!$B$6:$K$59,9,FALSE),VLOOKUP(D13,食物数据库V3!$B$6:$K$59,9,FALSE))),0)) -> 0 | H13: =IFERROR(G13*VLOOKUP(D13,食物数据库V3!$B$6:$K$59,2,FALSE)/100,0) -> 0 | I13: =IFERROR(G13*VLOOKUP(D13,食物数据库V3!$B$6:$K$59,3,FALSE)/100,0) -> 0 | J13: =IFERROR(G13*VLOOKUP(D13,食物数据库V3!$B$6:$K$59,4,FALSE)/100,0) -> 0 | K13: =IFERROR(G13*VLOOKUP(D13,食物数据库V3!$B$6:$K$59,5,FALSE)/100,0) -> 0
A14: 午餐 | B14: 1 | C14: 主食 | D14: 熟米饭 | E14: =IF(D14="","",IFERROR(VLOOKUP(D14,食物数据库V3!$B$6:$K$59,8,FALSE),"")) -> 熟重 | F14: 180 | G14: =IF(OR(D14="",F14=""),0,IFERROR(F14*IF(OR(VLOOKUP(D14,食物数据库V3!$B$6:$K$59,7,FALSE)="无需换算",E14=VLOOKUP(D14,食物数据库V3!$B$6:$K$59,7,FALSE)),1,IF(E14="熟重",1/VLOOKUP(D14,食物数据库V3!$B$6:$K$59,9,FALSE),VLOOKUP(D14,食物数据库V3!$B$6:$K$59,9,FALSE))),0)) -> 180 | H14: =IFERROR(G14*VLOOKUP(D14,食物数据库V3!$B$6:$K$59,2,FALSE)/100,0) -> 54 | I14: =IFERROR(G14*VLOOKUP(D14,食物数据库V3!$B$6:$K$59,3,FALSE)/100,0) -> 4.68 | J14: =IFERROR(G14*VLOOKUP(D14,食物数据库V3!$B$6:$K$59,4,FALSE)/100,0) -> 0.54 | K14: =IFERROR(G14*VLOOKUP(D14,食物数据库V3!$B$6:$K$59,5,FALSE)/100,0) -> 239.4
A15: 午餐 | B15: 2 | C15: 蛋白质 | D15: 鸡胸肉（生） | E15: =IF(D15="","",IFERROR(VLOOKUP(D15,食物数据库V3!$B$6:$K$59,8,FALSE),"")) -> 生重 | F15: 180 | G15: =IF(OR(D15="",F15=""),0,IFERROR(F15*IF(OR(VLOOKUP(D15,食物数据库V3!$B$6:$K$59,7,FALSE)="无需换算",E15=VLOOKUP(D15,食物数据库V3!$B$6:$K$59,7,FALSE)),1,IF(E15="熟重",1/VLOOKUP(D15,食物数据库V3!$B$6:$K$59,9,FALSE),VLOOKUP(D15,食物数据库V3!$B$6:$K$59,9,FALSE))),0)) -> 180 | H15: =IFERROR(G15*VLOOKUP(D15,食物数据库V3!$B$6:$K$59,2,FALSE)/100,0) -> 0 | I15: =IFERROR(G15*VLOOKUP(D15,食物数据库V3!$B$6:$K$59,3,FALSE)/100,0) -> 39.6 | J15: =IFERROR(G15*VLOOKUP(D15,食物数据库V3!$B$6:$K$59,4,FALSE)/100,0) -> 2.7 | K15: =IFERROR(G15*VLOOKUP(D15,食物数据库V3!$B$6:$K$59,5,FALSE)/100,0) -> 183.6
A16: 午餐 | B16: 3 | C16: 脂肪 | D16: 橄榄油 | E16: =IF(D16="","",IFERROR(VLOOKUP(D16,食物数据库V3!$B$6:$K$59,8,FALSE),"")) -> 熟重 | F16: 10 | G16: =IF(OR(D16="",F16=""),0,IFERROR(F16*IF(OR(VLOOKUP(D16,食物数据库V3!$B$6:$K$59,7,FALSE)="无需换算",E16=VLOOKUP(D16,食物数据库V3!$B$6:$K$59,7,FALSE)),1,IF(E16="熟重",1/VLOOKUP(D16,食物数据库V3!$B$6:$K$59,9,FALSE),VLOOKUP(D16,食物数据库V3!$B$6:$K$59,9,FALSE))),0)) -> 10 | H16: =IFERROR(G16*VLOOKUP(D16,食物数据库V3!$B$6:$K$59,2,FALSE)/100,0) -> 0 | I16: =IFERROR(G16*VLOOKUP(D16,食物数据库V3!$B$6:$K$59,3,FALSE)/100,0) -> 0 | J16: =IFERROR(G16*VLOOKUP(D16,食物数据库V3!$B$6:$K$59,4,FALSE)/100,0) -> 10 | K16: =IFERROR(G16*VLOOKUP(D16,食物数据库V3!$B$6:$K$59,5,FALSE)/100,0) -> 90
A17: 午餐 | B17: 4 | C17: 蔬菜 | D17: 西兰花 | E17: =IF(D17="","",IFERROR(VLOOKUP(D17,食物数据库V3!$B$6:$K$59,8,FALSE),"")) -> 生重 | F17: 200 | G17: =IF(OR(D17="",F17=""),0,IFERROR(F17*IF(OR(VLOOKUP(D17,食物数据库V3!$B$6:$K$59,7,FALSE)="无需换算",E17=VLOOKUP(D17,食物数据库V3!$B$6:$K$59,7,FALSE)),1,IF(E17="熟重",1/VLOOKUP(D17,食物数据库V3!$B$6:$K$59,9,FALSE),VLOOKUP(D17,食物数据库V3!$B$6:$K$59,9,FALSE))),0)) -> 200 | H17: =IFERROR(G17*VLOOKUP(D17,食物数据库V3!$B$6:$K$59,2,FALSE)/100,0) -> 14 | I17: =IFERROR(G17*VLOOKUP(D17,食物数据库V3!$B$6:$K$59,3,FALSE)/100,0) -> 5.6 | J17: =IFERROR(G17*VLOOKUP(D17,食物数据库V3!$B$6:$K$59,4,FALSE)/100,0) -> 0.8 | K17: =IFERROR(G17*VLOOKUP(D17,食物数据库V3!$B$6:$K$59,5,FALSE)/100,0) -> 86
A18: 午餐 | B18: 5 | E18: =IF(D18="","",IFERROR(VLOOKUP(D18,食物数据库V3!$B$6:$K$59,8,FALSE),"")) | G18: =IF(OR(D18="",F18=""),0,IFERROR(F18*IF(OR(VLOOKUP(D18,食物数据库V3!$B$6:$K$59,7,FALSE)="无需换算",E18=VLOOKUP(D18,食物数据库V3!$B$6:$K$59,7,FALSE)),1,IF(E18="熟重",1/VLOOKUP(D18,食物数据库V3!$B$6:$K$59,9,FALSE),VLOOKUP(D18,食物数据库V3!$B$6:$K$59,9,FALSE))),0)) -> 0 | H18: =IFERROR(G18*VLOOKUP(D18,食物数据库V3!$B$6:$K$59,2,FALSE)/100,0) -> 0 | I18: =IFERROR(G18*VLOOKUP(D18,食物数据库V3!$B$6:$K$59,3,FALSE)/100,0) -> 0 | J18: =IFERROR(G18*VLOOKUP(D18,食物数据库V3!$B$6:$K$59,4,FALSE)/100,0) -> 0 | K18: =IFERROR(G18*VLOOKUP(D18,食物数据库V3!$B$6:$K$59,5,FALSE)/100,0) -> 0
A19: 午餐 | B19: 6 | E19: =IF(D19="","",IFERROR(VLOOKUP(D19,食物数据库V3!$B$6:$K$59,8,FALSE),"")) | G19: =IF(OR(D19="",F19=""),0,IFERROR(F19*IF(OR(VLOOKUP(D19,食物数据库V3!$B$6:$K$59,7,FALSE)="无需换算",E19=VLOOKUP(D19,食物数据库V3!$B$6:$K$59,7,FALSE)),1,IF(E19="熟重",1/VLOOKUP(D19,食物数据库V3!$B$6:$K$59,9,FALSE),VLOOKUP(D19,食物数据库V3!$B$6:$K$59,9,FALSE))),0)) -> 0 | H19: =IFERROR(G19*VLOOKUP(D19,食物数据库V3!$B$6:$K$59,2,FALSE)/100,0) -> 0 | I19: =IFERROR(G19*VLOOKUP(D19,食物数据库V3!$B$6:$K$59,3,FALSE)/100,0) -> 0 | J19: =IFERROR(G19*VLOOKUP(D19,食物数据库V3!$B$6:$K$59,4,FALSE)/100,0) -> 0 | K19: =IFERROR(G19*VLOOKUP(D19,食物数据库V3!$B$6:$K$59,5,FALSE)/100,0) -> 0
A20: 练前餐 | B20: 1 | C20: 主食 | D20: 红薯（熟） | E20: =IF(D20="","",IFERROR(VLOOKUP(D20,食物数据库V3!$B$6:$K$59,8,FALSE),"")) -> 熟重 | F20: 150 | G20: =IF(OR(D20="",F20=""),0,IFERROR(F20*IF(OR(VLOOKUP(D20,食物数据库V3!$B$6:$K$59,7,FALSE)="无需换算",E20=VLOOKUP(D20,食物数据库V3!$B$6:$K$59,7,FALSE)),1,IF(E20="熟重",1/VLOOKUP(D20,食物数据库V3!$B$6:$K$59,9,FALSE),VLOOKUP(D20,食物数据库V3!$B$6:$K$59,9,FALSE))),0)) -> 150 | H20: =IFERROR(G20*VLOOKUP(D20,食物数据库V3!$B$6:$K$59,2,FALSE)/100,0) -> 30.15 | I20: =IFERROR(G20*VLOOKUP(D20,食物数据库V3!$B$6:$K$59,3,FALSE)/100,0) -> 2.4 | J20: =IFERROR(G20*VLOOKUP(D20,食物数据库V3!$B$6:$K$59,4,FALSE)/100,0) -> 0.15 | K20: =IFERROR(G20*VLOOKUP(D20,食物数据库V3!$B$6:$K$59,5,FALSE)/100,0) -> 132
A21: 练前餐 | B21: 2 | E21: =IF(D21="","",IFERROR(VLOOKUP(D21,食物数据库V3!$B$6:$K$59,8,FALSE),"")) | G21: =IF(OR(D21="",F21=""),0,IFERROR(F21*IF(OR(VLOOKUP(D21,食物数据库V3!$B$6:$K$59,7,FALSE)="无需换算",E21=VLOOKUP(D21,食物数据库V3!$B$6:$K$59,7,FALSE)),1,IF(E21="熟重",1/VLOOKUP(D21,食物数据库V3!$B$6:$K$59,9,FALSE),VLOOKUP(D21,食物数据库V3!$B$6:$K$59,9,FALSE))),0)) -> 0 | H21: =IFERROR(G21*VLOOKUP(D21,食物数据库V3!$B$6:$K$59,2,FALSE)/100,0) -> 0 | I21: =IFERROR(G21*VLOOKUP(D21,食物数据库V3!$B$6:$K$59,3,FALSE)/100,0) -> 0 | J21: =IFERROR(G21*VLOOKUP(D21,食物数据库V3!$B$6:$K$59,4,FALSE)/100,0) -> 0 | K21: =IFERROR(G21*VLOOKUP(D21,食物数据库V3!$B$6:$K$59,5,FALSE)/100,0) -> 0
A22: 练前餐 | B22: 3 | E22: =IF(D22="","",IFERROR(VLOOKUP(D22,食物数据库V3!$B$6:$K$59,8,FALSE),"")) | G22: =IF(OR(D22="",F22=""),0,IFERROR(F22*IF(OR(VLOOKUP(D22,食物数据库V3!$B$6:$K$59,7,FALSE)="无需换算",E22=VLOOKUP(D22,食物数据库V3!$B$6:$K$59,7,FALSE)),1,IF(E22="熟重",1/VLOOKUP(D22,食物数据库V3!$B$6:$K$59,9,FALSE),VLOOKUP(D22,食物数据库V3!$B$6:$K$59,9,FALSE))),0)) -> 0 | H22: =IFERROR(G22*VLOOKUP(D22,食物数据库V3!$B$6:$K$59,2,FALSE)/100,0) -> 0 | I22: =IFERROR(G22*VLOOKUP(D22,食物数据库V3!$B$6:$K$59,3,FALSE)/100,0) -> 0 | J22: =IFERROR(G22*VLOOKUP(D22,食物数据库V3!$B$6:$K$59,4,FALSE)/100,0) -> 0 | K22: =IFERROR(G22*VLOOKUP(D22,食物数据库V3!$B$6:$K$59,5,FALSE)/100,0) -> 0
A23: 练前餐 | B23: 4 | E23: =IF(D23="","",IFERROR(VLOOKUP(D23,食物数据库V3!$B$6:$K$59,8,FALSE),"")) | G23: =IF(OR(D23="",F23=""),0,IFERROR(F23*IF(OR(VLOOKUP(D23,食物数据库V3!$B$6:$K$59,7,FALSE)="无需换算",E23=VLOOKUP(D23,食物数据库V3!$B$6:$K$59,7,FALSE)),1,IF(E23="熟重",1/VLOOKUP(D23,食物数据库V3!$B$6:$K$59,9,FALSE),VLOOKUP(D23,食物数据库V3!$B$6:$K$59,9,FALSE))),0)) -> 0 | H23: =IFERROR(G23*VLOOKUP(D23,食物数据库V3!$B$6:$K$59,2,FALSE)/100,0) -> 0 | I23: =IFERROR(G23*VLOOKUP(D23,食物数据库V3!$B$6:$K$59,3,FALSE)/100,0) -> 0 | J23: =IFERROR(G23*VLOOKUP(D23,食物数据库V3!$B$6:$K$59,4,FALSE)/100,0) -> 0 | K23: =IFERROR(G23*VLOOKUP(D23,食物数据库V3!$B$6:$K$59,5,FALSE)/100,0) -> 0
A24: 练前餐 | B24: 5 | E24: =IF(D24="","",IFERROR(VLOOKUP(D24,食物数据库V3!$B$6:$K$59,8,FALSE),"")) | G24: =IF(OR(D24="",F24=""),0,IFERROR(F24*IF(OR(VLOOKUP(D24,食物数据库V3!$B$6:$K$59,7,FALSE)="无需换算",E24=VLOOKUP(D24,食物数据库V3!$B$6:$K$59,7,FALSE)),1,IF(E24="熟重",1/VLOOKUP(D24,食物数据库V3!$B$6:$K$59,9,FALSE),VLOOKUP(D24,食物数据库V3!$B$6:$K$59,9,FALSE))),0)) -> 0 | H24: =IFERROR(G24*VLOOKUP(D24,食物数据库V3!$B$6:$K$59,2,FALSE)/100,0) -> 0 | I24: =IFERROR(G24*VLOOKUP(D24,食物数据库V3!$B$6:$K$59,3,FALSE)/100,0) -> 0 | J24: =IFERROR(G24*VLOOKUP(D24,食物数据库V3!$B$6:$K$59,4,FALSE)/100,0) -> 0 | K24: =IFERROR(G24*VLOOKUP(D24,食物数据库V3!$B$6:$K$59,5,FALSE)/100,0) -> 0
A25: 练前餐 | B25: 6 | E25: =IF(D25="","",IFERROR(VLOOKUP(D25,食物数据库V3!$B$6:$K$59,8,FALSE),"")) | G25: =IF(OR(D25="",F25=""),0,IFERROR(F25*IF(OR(VLOOKUP(D25,食物数据库V3!$B$6:$K$59,7,FALSE)="无需换算",E25=VLOOKUP(D25,食物数据库V3!$B$6:$K$59,7,FALSE)),1,IF(E25="熟重",1/VLOOKUP(D25,食物数据库V3!$B$6:$K$59,9,FALSE),VLOOKUP(D25,食物数据库V3!$B$6:$K$59,9,FALSE))),0)) -> 0 | H25: =IFERROR(G25*VLOOKUP(D25,食物数据库V3!$B$6:$K$59,2,FALSE)/100,0) -> 0 | I25: =IFERROR(G25*VLOOKUP(D25,食物数据库V3!$B$6:$K$59,3,FALSE)/100,0) -> 0 | J25: =IFERROR(G25*VLOOKUP(D25,食物数据库V3!$B$6:$K$59,4,FALSE)/100,0) -> 0 | K25: =IFERROR(G25*VLOOKUP(D25,食物数据库V3!$B$6:$K$59,5,FALSE)/100,0) -> 0
A26: 晚饭/练后餐 | B26: 1 | C26: 主食 | D26: 荞麦面（熟） | E26: =IF(D26="","",IFERROR(VLOOKUP(D26,食物数据库V3!$B$6:$K$59,8,FALSE),"")) -> 熟重 | F26: 180 | G26: =IF(OR(D26="",F26=""),0,IFERROR(F26*IF(OR(VLOOKUP(D26,食物数据库V3!$B$6:$K$59,7,FALSE)="无需换算",E26=VLOOKUP(D26,食物数据库V3!$B$6:$K$59,7,FALSE)),1,IF(E26="熟重",1/VLOOKUP(D26,食物数据库V3!$B$6:$K$59,9,FALSE),VLOOKUP(D26,食物数据库V3!$B$6:$K$59,9,FALSE))),0)) -> 180 | H26: =IFERROR(G26*VLOOKUP(D26,食物数据库V3!$B$6:$K$59,2,FALSE)/100,0) -> 48.6 | I26: =IFERROR(G26*VLOOKUP(D26,食物数据库V3!$B$6:$K$59,3,FALSE)/100,0) -> 9.18 | J26: =IFERROR(G26*VLOOKUP(D26,食物数据库V3!$B$6:$K$59,4,FALSE)/100,0) -> 0.18 | K26: =IFERROR(G26*VLOOKUP(D26,食物数据库V3!$B$6:$K$59,5,FALSE)/100,0) -> 232.2
A27: 晚饭/练后餐 | B27: 2 | C27: 蛋白质 | D27: 鸡胸肉（生） | E27: =IF(D27="","",IFERROR(VLOOKUP(D27,食物数据库V3!$B$6:$K$59,8,FALSE),"")) -> 生重 | F27: 180 | G27: =IF(OR(D27="",F27=""),0,IFERROR(F27*IF(OR(VLOOKUP(D27,食物数据库V3!$B$6:$K$59,7,FALSE)="无需换算",E27=VLOOKUP(D27,食物数据库V3!$B$6:$K$59,7,FALSE)),1,IF(E27="熟重",1/VLOOKUP(D27,食物数据库V3!$B$6:$K$59,9,FALSE),VLOOKUP(D27,食物数据库V3!$B$6:$K$59,9,FALSE))),0)) -> 180 | H27: =IFERROR(G27*VLOOKUP(D27,食物数据库V3!$B$6:$K$59,2,FALSE)/100,0) -> 0 | I27: =IFERROR(G27*VLOOKUP(D27,食物数据库V3!$B$6:$K$59,3,FALSE)/100,0) -> 39.6 | J27: =IFERROR(G27*VLOOKUP(D27,食物数据库V3!$B$6:$K$59,4,FALSE)/100,0) -> 2.7 | K27: =IFERROR(G27*VLOOKUP(D27,食物数据库V3!$B$6:$K$59,5,FALSE)/100,0) -> 183.6
A28: 晚饭/练后餐 | B28: 3 | C28: 脂肪 | D28: 橄榄油 | E28: =IF(D28="","",IFERROR(VLOOKUP(D28,食物数据库V3!$B$6:$K$59,8,FALSE),"")) -> 熟重 | F28: 10 | G28: =IF(OR(D28="",F28=""),0,IFERROR(F28*IF(OR(VLOOKUP(D28,食物数据库V3!$B$6:$K$59,7,FALSE)="无需换算",E28=VLOOKUP(D28,食物数据库V3!$B$6:$K$59,7,FALSE)),1,IF(E28="熟重",1/VLOOKUP(D28,食物数据库V3!$B$6:$K$59,9,FALSE),VLOOKUP(D28,食物数据库V3!$B$6:$K$59,9,FALSE))),0)) -> 10 | H28: =IFERROR(G28*VLOOKUP(D28,食物数据库V3!$B$6:$K$59,2,FALSE)/100,0) -> 0 | I28: =IFERROR(G28*VLOOKUP(D28,食物数据库V3!$B$6:$K$59,3,FALSE)/100,0) -> 0 | J28: =IFERROR(G28*VLOOKUP(D28,食物数据库V3!$B$6:$K$59,4,FALSE)/100,0) -> 10 | K28: =IFERROR(G28*VLOOKUP(D28,食物数据库V3!$B$6:$K$59,5,FALSE)/100,0) -> 90
A29: 晚饭/练后餐 | B29: 4 | C29: 蔬菜 | D29: 胡萝卜 | E29: =IF(D29="","",IFERROR(VLOOKUP(D29,食物数据库V3!$B$6:$K$59,8,FALSE),"")) -> 生重 | F29: 200 | G29: =IF(OR(D29="",F29=""),0,IFERROR(F29*IF(OR(VLOOKUP(D29,食物数据库V3!$B$6:$K$59,7,FALSE)="无需换算",E29=VLOOKUP(D29,食物数据库V3!$B$6:$K$59,7,FALSE)),1,IF(E29="熟重",1/VLOOKUP(D29,食物数据库V3!$B$6:$K$59,9,FALSE),VLOOKUP(D29,食物数据库V3!$B$6:$K$59,9,FALSE))),0)) -> 200 | H29: =IFERROR(G29*VLOOKUP(D29,食物数据库V3!$B$6:$K$59,2,FALSE)/100,0) -> 19.2 | I29: =IFERROR(G29*VLOOKUP(D29,食物数据库V3!$B$6:$K$59,3,FALSE)/100,0) -> 1.8 | J29: =IFERROR(G29*VLOOKUP(D29,食物数据库V3!$B$6:$K$59,4,FALSE)/100,0) -> 0.4 | K29: =IFERROR(G29*VLOOKUP(D29,食物数据库V3!$B$6:$K$59,5,FALSE)/100,0) -> 88
A30: 晚饭/练后餐 | B30: 5 | E30: =IF(D30="","",IFERROR(VLOOKUP(D30,食物数据库V3!$B$6:$K$59,8,FALSE),"")) | G30: =IF(OR(D30="",F30=""),0,IFERROR(F30*IF(OR(VLOOKUP(D30,食物数据库V3!$B$6:$K$59,7,FALSE)="无需换算",E30=VLOOKUP(D30,食物数据库V3!$B$6:$K$59,7,FALSE)),1,IF(E30="熟重",1/VLOOKUP(D30,食物数据库V3!$B$6:$K$59,9,FALSE),VLOOKUP(D30,食物数据库V3!$B$6:$K$59,9,FALSE))),0)) -> 0 | H30: =IFERROR(G30*VLOOKUP(D30,食物数据库V3!$B$6:$K$59,2,FALSE)/100,0) -> 0 | I30: =IFERROR(G30*VLOOKUP(D30,食物数据库V3!$B$6:$K$59,3,FALSE)/100,0) -> 0 | J30: =IFERROR(G30*VLOOKUP(D30,食物数据库V3!$B$6:$K$59,4,FALSE)/100,0) -> 0 | K30: =IFERROR(G30*VLOOKUP(D30,食物数据库V3!$B$6:$K$59,5,FALSE)/100,0) -> 0
A31: 晚饭/练后餐 | B31: 6 | E31: =IF(D31="","",IFERROR(VLOOKUP(D31,食物数据库V3!$B$6:$K$59,8,FALSE),"")) | G31: =IF(OR(D31="",F31=""),0,IFERROR(F31*IF(OR(VLOOKUP(D31,食物数据库V3!$B$6:$K$59,7,FALSE)="无需换算",E31=VLOOKUP(D31,食物数据库V3!$B$6:$K$59,7,FALSE)),1,IF(E31="熟重",1/VLOOKUP(D31,食物数据库V3!$B$6:$K$59,9,FALSE),VLOOKUP(D31,食物数据库V3!$B$6:$K$59,9,FALSE))),0)) -> 0 | H31: =IFERROR(G31*VLOOKUP(D31,食物数据库V3!$B$6:$K$59,2,FALSE)/100,0) -> 0 | I31: =IFERROR(G31*VLOOKUP(D31,食物数据库V3!$B$6:$K$59,3,FALSE)/100,0) -> 0 | J31: =IFERROR(G31*VLOOKUP(D31,食物数据库V3!$B$6:$K$59,4,FALSE)/100,0) -> 0 | K31: =IFERROR(G31*VLOOKUP(D31,食物数据库V3!$B$6:$K$59,5,FALSE)/100,0) -> 0
A33: ③ 每餐与全天营养汇总 | H33: ④ 全天目标对比
A34: 餐次 | B34: 食物种数 | C34: 碳水(g) | D34: 蛋白质(g) | E34: 脂肪(g) | F34: 热量(kcal) | H34: 项目 | I34: 目标 | J34: 实际 | K34: 差异 | L34: 状态
A35: 早餐 | B35: =COUNTIF(D8:D13,"<>") -> 3 | C35: =SUM(H8:H13) -> 35.82 | D35: =SUM(I8:I13) -> 25.12 | E35: =SUM(J8:J13) -> 19.15 | F35: =SUM(K8:K13) -> 417.5 | H35: 碳水(g) | I35: =H4 -> 150.84507 | J35: =C39 -> 201.77 | K35: =J35-I35 -> 50.92493 | L35: =IF(OR(I35="",I35=0),"",IF(ABS(K35)<=I35*5%,"接近目标",IF(K35>0,"偏高","偏低"))) -> 偏高
A36: 午餐 | B36: =COUNTIF(D14:D19,"<>") -> 4 | C36: =SUM(H14:H19) -> 68 | D36: =SUM(I14:I19) -> 49.88 | E36: =SUM(J14:J19) -> 14.04 | F36: =SUM(K14:K19) -> 599 | H36: 蛋白质(g) | I36: =J4 -> 119 | J36: =D39 -> 127.98 | K36: =J36-I36 -> 8.98 | L36: =IF(OR(I36="",I36=0),"",IF(ABS(K36)<=I36*5%,"接近目标",IF(K36>0,"偏高","偏低"))) -> 偏高
A37: 练前餐 | B37: =COUNTIF(D20:D25,"<>") -> 1 | C37: =SUM(H20:H25) -> 30.15 | D37: =SUM(I20:I25) -> 2.4 | E37: =SUM(J20:J25) -> 0.15 | F37: =SUM(K20:K25) -> 132 | H37: 脂肪(g) | I37: =L4 -> 76.513302 | J37: =E39 -> 46.62 | K37: =J37-I37 -> -29.893302 | L37: =IF(OR(I37="",I37=0),"",IF(ABS(K37)<=I37*5%,"接近目标",IF(K37>0,"偏高","偏低"))) -> 偏低
A38: 晚饭/练后餐 | B38: =COUNTIF(D26:D31,"<>") -> 4 | C38: =SUM(H26:H31) -> 67.8 | D38: =SUM(I26:I31) -> 50.58 | E38: =SUM(J26:J31) -> 13.28 | F38: =SUM(K26:K31) -> 593.8 | H38: 热量(kcal) | I38: =H5 -> 1768 | J38: =F39 -> 1742.3 | K38: =J38-I38 -> -25.7 | L38: =IF(OR(I38="",I38=0),"",IF(ABS(K38)<=I38*5%,"接近目标",IF(K38>0,"偏高","偏低"))) -> 接近目标
A39: 全天合计 | B39: =SUM(B35:B38) -> 12 | C39: =SUM(C35:C38) -> 201.77 | D39: =SUM(D35:D38) -> 127.98 | E39: =SUM(E35:E38) -> 46.62 | F39: =SUM(F35:F38) -> 1742.3
A41: ⑤ 使用提示
A42: • 每餐固定预留6个槽位；先选类别，再从对应下拉列表选择食物，未使用的槽位保持空白即可。
A43: • 黄色区域为输入项：类别、食物、称重口径和重量均可修改；示例搭配仅用于展示，可全部替换。
...

Sheet V6周期饮食总览
A1: 碳循环减脂 V6｜整个循环的每日分餐营养目标
A3: 循环长度改变后，本表自动启用或停用对应循环日；训练日含纯碳水练前餐
A4: 循环日 | B4: 名称 | C4: 碳类型 | D4: 训练 | E4: 训练时间 | F4: 餐食模板 | G4: 日碳水 | H4: 日蛋白 | I4: 日脂肪 | J4: 早餐碳水 | K4: 早餐蛋白 | L4: 早餐脂肪 | M4: 午餐碳水 | N4: 午餐蛋白 | O4: 午餐脂肪 | P4: 练前碳水 | Q4: 练前蛋白 | R4: 练前脂肪 | S4: 晚/练后碳水 | T4: 晚/练后蛋白 | U4: 晚/练后脂肪
A5: 1 | B5: =V6周期计划!B20 -> 第1天 | C5: =IF(B5="未启用","",V6周期计划!C20) -> 中碳日 | D5: =IF(B5="未启用","",V6周期计划!D20) -> 是 | E5: =IF(B5="未启用","",V6周期计划!E20) -> 晚饭前 | F5: =IF(B5="未启用","",V6周期计划!F20) -> 训练日模板 | G5: =IF(B5="未启用","",V6周期计划!G20) -> 150.84507 | H5: =IF(B5="未启用","",V6周期计划!H20) -> 119 | I5: =IF(B5="未启用","",V6周期计划!I20) -> 76.513302 | J5: =IF(B5="未启用","",G5*IF(D5="是",V6设置!$B15,V6设置!$B23)) -> 37.711268 | K5: =IF(B5="未启用","",H5*IF(D5="是",V6设置!$C15,V6设置!$C23)) -> 23.8 | L5: =IF(B5="未启用","",I5*IF(D5="是",V6设置!$D15,V6设置!$D23)) -> 15.30266 | M5: =IF(B5="未启用","",G5*IF(D5="是",V6设置!$B16,V6设置!$B24)) -> 37.711268 | N5: =IF(B5="未启用","",H5*IF(D5="是",V6设置!$C16,V6设置!$C24)) -> 47.6 | O5: =IF(B5="未启用","",I5*IF(D5="是",V6设置!$D16,V6设置!$D24)) -> 30.605321 | P5: =IF(B5="未启用","",G5*IF(D5="是",V6设置!$B17,V6设置!$B25)) -> 15.084507 | Q5: =IF(B5="未启用","",H5*IF(D5="是",V6设置!$C17,V6设置!$C25)) -> 0 | R5: =IF(B5="未启用","",I5*IF(D5="是",V6设置!$D17,V6设置!$D25)) -> 0 | S5: =IF(B5="未启用","",G5*IF(D5="是",V6设置!$B18,V6设置!$B26)) -> 60.338028 | T5: =IF(B5="未启用","",H5*IF(D5="是",V6设置!$C18,V6设置!$C26)) -> 47.6 | U5: =IF(B5="未启用","",I5*IF(D5="是",V6设置!$D18,V6设置!$D26)) -> 30.605321
A6: 2 | B6: =V6周期计划!B21 -> 第2天 | C6: =IF(B6="未启用","",V6周期计划!C21) -> 低碳日 | D6: =IF(B6="未启用","",V6周期计划!D21) -> 否 | E6: =IF(B6="未启用","",V6周期计划!E21) -> - | F6: =IF(B6="未启用","",V6周期计划!F21) -> 休息日模板 | G6: =IF(B6="未启用","",V6周期计划!G21) -> 100.56338 | H6: =IF(B6="未启用","",V6周期计划!H21) -> 119 | I6: =IF(B6="未启用","",V6周期计划!I21) -> 98.86072 | J6: =IF(B6="未启用","",G6*IF(D6="是",V6设置!$B15,V6设置!$B23)) -> 30.169014 | K6: =IF(B6="未启用","",H6*IF(D6="是",V6设置!$C15,V6设置!$C23)) -> 35.7 | L6: =IF(B6="未启用","",I6*IF(D6="是",V6设置!$D15,V6设置!$D23)) -> 29.658216 | M6: =IF(B6="未启用","",G6*IF(D6="是",V6设置!$B16,V6设置!$B24)) -> 40.225352 | N6: =IF(B6="未启用","",H6*IF(D6="是",V6设置!$C16,V6设置!$C24)) -> 47.6 | O6: =IF(B6="未启用","",I6*IF(D6="是",V6设置!$D16,V6设置!$D24)) -> 39.544288 | P6: =IF(B6="未启用","",G6*IF(D6="是",V6设置!$B17,V6设置!$B25)) -> 0 | Q6: =IF(B6="未启用","",H6*IF(D6="是",V6设置!$C17,V6设置!$C25)) -> 0 | R6: =IF(B6="未启用","",I6*IF(D6="是",V6设置!$D17,V6设置!$D25)) -> 0 | S6: =IF(B6="未启用","",G6*IF(D6="是",V6设置!$B18,V6设置!$B26)) -> 30.169014 | T6: =IF(B6="未启用","",H6*IF(D6="是",V6设置!$C18,V6设置!$C26)) -> 35.7 | U6: =IF(B6="未启用","",I6*IF(D6="是",V6设置!$D18,V6设置!$D26)) -> 29.658216
A7: 3 | B7: =V6周期计划!B22 -> 第3天 | C7: =IF(B7="未启用","",V6周期计划!C22) -> 中碳日 | D7: =IF(B7="未启用","",V6周期计划!D22) -> 是 | E7: =IF(B7="未启用","",V6周期计划!E22) -> 晚饭前 | F7: =IF(B7="未启用","",V6周期计划!F22) -> 训练日模板 | G7: =IF(B7="未启用","",V6周期计划!G22) -> 150.84507 | H7: =IF(B7="未启用","",V6周期计划!H22) -> 119 | I7: =IF(B7="未启用","",V6周期计划!I22) -> 76.513302 | J7: =IF(B7="未启用","",G7*IF(D7="是",V6设置!$B15,V6设置!$B23)) -> 37.711268 | K7: =IF(B7="未启用","",H7*IF(D7="是",V6设置!$C15,V6设置!$C23)) -> 23.8 | L7: =IF(B7="未启用","",I7*IF(D7="是",V6设置!$D15,V6设置!$D23)) -> 15.30266 | M7: =IF(B7="未启用","",G7*IF(D7="是",V6设置!$B16,V6设置!$B24)) -> 37.711268 | N7: =IF(B7="未启用","",H7*IF(D7="是",V6设置!$C16,V6设置!$C24)) -> 47.6 | O7: =IF(B7="未启用","",I7*IF(D7="是",V6设置!$D16,V6设置!$D24)) -> 30.605321 | P7: =IF(B7="未启用","",G7*IF(D7="是",V6设置!$B17,V6设置!$B25)) -> 15.084507 | Q7: =IF(B7="未启用","",H7*IF(D7="是",V6设置!$C17,V6设置!$C25)) -> 0 | R7: =IF(B7="未启用","",I7*IF(D7="是",V6设置!$D17,V6设置!$D25)) -> 0 | S7: =IF(B7="未启用","",G7*IF(D7="是",V6设置!$B18,V6设置!$B26)) -> 60.338028 | T7: =IF(B7="未启用","",H7*IF(D7="是",V6设置!$C18,V6设置!$C26)) -> 47.6 | U7: =IF(B7="未启用","",I7*IF(D7="是",V6设置!$D18,V6设置!$D26)) -> 30.605321
A8: 4 | B8: =V6周期计划!B23 -> 第4天 | C8: =IF(B8="未启用","",V6周期计划!C23) -> 高碳日 | D8: =IF(B8="未启用","",V6周期计划!D23) -> 是 | E8: =IF(B8="未启用","",V6周期计划!E23) -> 晚饭前 | F8: =IF(B8="未启用","",V6周期计划!F23) -> 训练日模板 | G8: =IF(B8="未启用","",V6周期计划!G23) -> 268.16901 | H8: =IF(B8="未启用","",V6周期计划!H23) -> 119 | I8: =IF(B8="未启用","",V6周期计划!I23) -> 24.369327 | J8: =IF(B8="未启用","",G8*IF(D8="是",V6设置!$B15,V6设置!$B23)) -> 67.042254 | K8: =IF(B8="未启用","",H8*IF(D8="是",V6设置!$C15,V6设置!$C23)) -> 23.8 | L8: =IF(B8="未启用","",I8*IF(D8="是",V6设置!$D15,V6设置!$D23)) -> 4.8738654 | M8: =IF(B8="未启用","",G8*IF(D8="是",V6设置!$B16,V6设置!$B24)) -> 67.042254 | N8: =IF(B8="未启用","",H8*IF(D8="是",V6设置!$C16,V6设置!$C24)) -> 47.6 | O8: =IF(B8="未启用","",I8*IF(D8="是",V6设置!$D16,V6设置!$D24)) -> 9.7477308 | P8: =IF(B8="未启用","",G8*IF(D8="是",V6设置!$B17,V6设置!$B25)) -> 26.816901 | Q8: =IF(B8="未启用","",H8*IF(D8="是",V6设置!$C17,V6设置!$C25)) -> 0 | R8: =IF(B8="未启用","",I8*IF(D8="是",V6设置!$D17,V6设置!$D25)) -> 0 | S8: =IF(B8="未启用","",G8*IF(D8="是",V6设置!$B18,V6设置!$B26)) -> 107.26761 | T8: =IF(B8="未启用","",H8*IF(D8="是",V6设置!$C18,V6设置!$C26)) -> 47.6 | U8: =IF(B8="未启用","",I8*IF(D8="是",V6设置!$D18,V6设置!$D26)) -> 9.7477308
A9: 5 | B9: =V6周期计划!B24 -> 第5天 | C9: =IF(B9="未启用","",V6周期计划!C24) -> 低碳日 | D9: =IF(B9="未启用","",V6周期计划!D24) -> 否 | E9: =IF(B9="未启用","",V6周期计划!E24) -> - | F9: =IF(B9="未启用","",V6周期计划!F24) -> 休息日模板 | G9: =IF(B9="未启用","",V6周期计划!G24) -> 100.56338 | H9: =IF(B9="未启用","",V6周期计划!H24) -> 119 | I9: =IF(B9="未启用","",V6周期计划!I24) -> 98.86072 | J9: =IF(B9="未启用","",G9*IF(D9="是",V6设置!$B15,V6设置!$B23)) -> 30.169014 | K9: =IF(B9="未启用","",H9*IF(D9="是",V6设置!$C15,V6设置!$C23)) -> 35.7 | L9: =IF(B9="未启用","",I9*IF(D9="是",V6设置!$D15,V6设置!$D23)) -> 29.658216 | M9: =IF(B9="未启用","",G9*IF(D9="是",V6设置!$B16,V6设置!$B24)) -> 40.225352 | N9: =IF(B9="未启用","",H9*IF(D9="是",V6设置!$C16,V6设置!$C24)) -> 47.6 | O9: =IF(B9="未启用","",I9*IF(D9="是",V6设置!$D16,V6设置!$D24)) -> 39.544288 | P9: =IF(B9="未启用","",G9*IF(D9="是",V6设置!$B17,V6设置!$B25)) -> 0 | Q9: =IF(B9="未启用","",H9*IF(D9="是",V6设置!$C17,V6设置!$C25)) -> 0 | R9: =IF(B9="未启用","",I9*IF(D9="是",V6设置!$D17,V6设置!$D25)) -> 0 | S9: =IF(B9="未启用","",G9*IF(D9="是",V6设置!$B18,V6设置!$B26)) -> 30.169014 | T9: =IF(B9="未启用","",H9*IF(D9="是",V6设置!$C18,V6设置!$C26)) -> 35.7 | U9: =IF(B9="未启用","",I9*IF(D9="是",V6设置!$D18,V6设置!$D26)) -> 29.658216
A10: 6 | B10: =V6周期计划!B25 -> 第6天 | C10: =IF(B10="未启用","",V6周期计划!C25) -> 中碳日 | D10: =IF(B10="未启用","",V6周期计划!D25) -> 是 | E10: =IF(B10="未启用","",V6周期计划!E25) -> 晚饭前 | F10: =IF(B10="未启用","",V6周期计划!F25) -> 训练日模板 | G10: =IF(B10="未启用","",V6周期计划!G25) -> 150.84507 | H10: =IF(B10="未启用","",V6周期计划!H25) -> 119 | I10: =IF(B10="未启用","",V6周期计划!I25) -> 76.513302 | J10: =IF(B10="未启用","",G10*IF(D10="是",V6设置!$B15,V6设置!$B23)) -> 37.711268 | K10: =IF(B10="未启用","",H10*IF(D10="是",V6设置!$C15,V6设置!$C23)) -> 23.8 | L10: =IF(B10="未启用","",I10*IF(D10="是",V6设置!$D15,V6设置!$D23)) -> 15.30266 | M10: =IF(B10="未启用","",G10*IF(D10="是",V6设置!$B16,V6设置!$B24)) -> 37.711268 | N10: =IF(B10="未启用","",H10*IF(D10="是",V6设置!$C16,V6设置!$C24)) -> 47.6 | O10: =IF(B10="未启用","",I10*IF(D10="是",V6设置!$D16,V6设置!$D24)) -> 30.605321 | P10: =IF(B10="未启用","",G10*IF(D10="是",V6设置!$B17,V6设置!$B25)) -> 15.084507 | Q10: =IF(B10="未启用","",H10*IF(D10="是",V6设置!$C17,V6设置!$C25)) -> 0 | R10: =IF(B10="未启用","",I10*IF(D10="是",V6设置!$D17,V6设置!$D25)) -> 0 | S10: =IF(B10="未启用","",G10*IF(D10="是",V6设置!$B18,V6设置!$B26)) -> 60.338028 | T10: =IF(B10="未启用","",H10*IF(D10="是",V6设置!$C18,V6设置!$C26)) -> 47.6 | U10: =IF(B10="未启用","",I10*IF(D10="是",V6设置!$D18,V6设置!$D26)) -> 30.605321
A11: 7 | B11: =V6周期计划!B26 -> 第7天 | C11: =IF(B11="未启用","",V6周期计划!C26) -> 高碳日 | D11: =IF(B11="未启用","",V6周期计划!D26) -> 否 | E11: =IF(B11="未启用","",V6周期计划!E26) -> - | F11: =IF(B11="未启用","",V6周期计划!F26) -> 休息日模板 | G11: =IF(B11="未启用","",V6周期计划!G26) -> 268.16901 | H11: =IF(B11="未启用","",V6周期计划!H26) -> 119 | I11: =IF(B11="未启用","",V6周期计划!I26) -> 24.369327 | J11: =IF(B11="未启用","",G11*IF(D11="是",V6设置!$B15,V6设置!$B23)) -> 80.450704 | K11: =IF(B11="未启用","",H11*IF(D11="是",V6设置!$C15,V6设置!$C23)) -> 35.7 | L11: =IF(B11="未启用","",I11*IF(D11="是",V6设置!$D15,V6设置!$D23)) -> 7.3107981 | M11: =IF(B11="未启用","",G11*IF(D11="是",V6设置!$B16,V6设置!$B24)) -> 107.26761 | N11: =IF(B11="未启用","",H11*IF(D11="是",V6设置!$C16,V6设置!$C24)) -> 47.6 | O11: =IF(B11="未启用","",I11*IF(D11="是",V6设置!$D16,V6设置!$D24)) -> 9.7477308 | P11: =IF(B11="未启用","",G11*IF(D11="是",V6设置!$B17,V6设置!$B25)) -> 0 | Q11: =IF(B11="未启用","",H11*IF(D11="是",V6设置!$C17,V6设置!$C25)) -> 0 | R11: =IF(B11="未启用","",I11*IF(D11="是",V6设置!$D17,V6设置!$D25)) -> 0 | S11: =IF(B11="未启用","",G11*IF(D11="是",V6设置!$B18,V6设置!$B26)) -> 80.450704 | T11: =IF(B11="未启用","",H11*IF(D11="是",V6设置!$C18,V6设置!$C26)) -> 35.7 | U11: =IF(B11="未启用","",I11*IF(D11="是",V6设置!$D18,V6设置!$D26)) -> 7.3107981
A12: 8 | B12: =V6周期计划!B27 -> 未启用 | C12: =IF(B12="未启用","",V6周期计划!C27) | D12: =IF(B12="未启用","",V6周期计划!D27) | E12: =IF(B12="未启用","",V6周期计划!E27) | F12: =IF(B12="未启用","",V6周期计划!F27) | G12: =IF(B12="未启用","",V6周期计划!G27) | H12: =IF(B12="未启用","",V6周期计划!H27) | I12: =IF(B12="未启用","",V6周期计划!I27) | J12: =IF(B12="未启用","",G12*IF(D12="是",V6设置!$B15,V6设置!$B23)) | K12: =IF(B12="未启用","",H12*IF(D12="是",V6设置!$C15,V6设置!$C23)) | L12: =IF(B12="未启用","",I12*IF(D12="是",V6设置!$D15,V6设置!$D23)) | M12: =IF(B12="未启用","",G12*IF(D12="是",V6设置!$B16,V6设置!$B24)) | N12: =IF(B12="未启用","",H12*IF(D12="是",V6设置!$C16,V6设置!$C24)) | O12: =IF(B12="未启用","",I12*IF(D12="是",V6设置!$D16,V6设置!$D24)) | P12: =IF(B12="未启用","",G12*IF(D12="是",V6设置!$B17,V6设置!$B25)) | Q12: =IF(B12="未启用","",H12*IF(D12="是",V6设置!$C17,V6设置!$C25)) | R12: =IF(B12="未启用","",I12*IF(D12="是",V6设置!$D17,V6设置!$D25)) | S12: =IF(B12="未启用","",G12*IF(D12="是",V6设置!$B18,V6设置!$B26)) | T12: =IF(B12="未启用","",H12*IF(D12="是",V6设置!$C18,V6设置!$C26)) | U12: =IF(B12="未启用","",I12*IF(D12="是",V6设置!$D18,V6设置!$D26))
A13: 9 | B13: =V6周期计划!B28 -> 未启用 | C13: =IF(B13="未启用","",V6周期计划!C28) | D13: =IF(B13="未启用","",V6周期计划!D28) | E13: =IF(B13="未启用","",V6周期计划!E28) | F13: =IF(B13="未启用","",V6周期计划!F28) | G13: =IF(B13="未启用","",V6周期计划!G28) | H13: =IF(B13="未启用","",V6周期计划!H28) | I13: =IF(B13="未启用","",V6周期计划!I28) | J13: =IF(B13="未启用","",G13*IF(D13="是",V6设置!$B15,V6设置!$B23)) | K13: =IF(B13="未启用","",H13*IF(D13="是",V6设置!$C15,V6设置!$C23)) | L13: =IF(B13="未启用","",I13*IF(D13="是",V6设置!$D15,V6设置!$D23)) | M13: =IF(B13="未启用","",G13*IF(D13="是",V6设置!$B16,V6设置!$B24)) | N13: =IF(B13="未启用","",H13*IF(D13="是",V6设置!$C16,V6设置!$C24)) | O13: =IF(B13="未启用","",I13*IF(D13="是",V6设置!$D16,V6设置!$D24)) | P13: =IF(B13="未启用","",G13*IF(D13="是",V6设置!$B17,V6设置!$B25)) | Q13: =IF(B13="未启用","",H13*IF(D13="是",V6设置!$C17,V6设置!$C25)) | R13: =IF(B13="未启用","",I13*IF(D13="是",V6设置!$D17,V6设置!$D25)) | S13: =IF(B13="未启用","",G13*IF(D13="是",V6设置!$B18,V6设置!$B26)) | T13: =IF(B13="未启用","",H13*IF(D13="是",V6设置!$C18,V6设置!$C26)) | U13: =IF(B13="未启用","",I13*IF(D13="是",V6设置!$D18,V6设置!$D26))
A14: 10 | B14: =V6周期计划!B29 -> 未启用 | C14: =IF(B14="未启用","",V6周期计划!C29) | D14: =IF(B14="未启用","",V6周期计划!D29) | E14: =IF(B14="未启用","",V6周期计划!E29) | F14: =IF(B14="未启用","",V6周期计划!F29) | G14: =IF(B14="未启用","",V6周期计划!G29) | H14: =IF(B14="未启用","",V6周期计划!H29) | I14: =IF(B14="未启用","",V6周期计划!I29) | J14: =IF(B14="未启用","",G14*IF(D14="是",V6设置!$B15,V6设置!$B23)) | K14: =IF(B14="未启用","",H14*IF(D14="是",V6设置!$C15,V6设置!$C23)) | L14: =IF(B14="未启用","",I14*IF(D14="是",V6设置!$D15,V6设置!$D23)) | M14: =IF(B14="未启用","",G14*IF(D14="是",V6设置!$B16,V6设置!$B24)) | N14: =IF(B14="未启用","",H14*IF(D14="是",V6设置!$C16,V6设置!$C24)) | O14: =IF(B14="未启用","",I14*IF(D14="是",V6设置!$D16,V6设置!$D24)) | P14: =IF(B14="未启用","",G14*IF(D14="是",V6设置!$B17,V6设置!$B25)) | Q14: =IF(B14="未启用","",H14*IF(D14="是",V6设置!$C17,V6设置!$C25)) | R14: =IF(B14="未启用","",I14*IF(D14="是",V6设置!$D17,V6设置!$D25)) | S14: =IF(B14="未启用","",G14*IF(D14="是",V6设置!$B18,V6设置!$B26)) | T14: =IF(B14="未启用","",H14*IF(D14="是",V6设置!$C18,V6设置!$C26)) | U14: =IF(B14="未启用","",I14*IF(D14="是",V6设置!$D18,V6设置!$D26))
A15: 11 | B15: =V6周期计划!B30 -> 未启用 | C15: =IF(B15="未启用","",V6周期计划!C30) | D15: =IF(B15="未启用","",V6周期计划!D30) | E15: =IF(B15="未启用","",V6周期计划!E30) | F15: =IF(B15="未启用","",V6周期计划!F30) | G15: =IF(B15="未启用","",V6周期计划!G30) | H15: =IF(B15="未启用","",V6周期计划!H30) | I15: =IF(B15="未启用","",V6周期计划!I30) | J15: =IF(B15="未启用","",G15*IF(D15="是",V6设置!$B15,V6设置!$B23)) | K15: =IF(B15="未启用","",H15*IF(D15="是",V6设置!$C15,V6设置!$C23)) | L15: =IF(B15="未启用","",I15*IF(D15="是",V6设置!$D15,V6设置!$D23)) | M15: =IF(B15="未启用","",G15*IF(D15="是",V6设置!$B16,V6设置!$B24)) | N15: =IF(B15="未启用","",H15*IF(D15="是",V6设置!$C16,V6设置!$C24)) | O15: =IF(B15="未启用","",I15*IF(D15="是",V6设置!$D16,V6设置!$D24)) | P15: =IF(B15="未启用","",G15*IF(D15="是",V6设置!$B17,V6设置!$B25)) | Q15: =IF(B15="未启用","",H15*IF(D15="是",V6设置!$C17,V6设置!$C25)) | R15: =IF(B15="未启用","",I15*IF(D15="是",V6设置!$D17,V6设置!$D25)) | S15: =IF(B15="未启用","",G15*IF(D15="是",V6设置!$B18,V6设置!$B26)) | T15: =IF(B15="未启用","",H15*IF(D15="是",V6设置!$C18,V6设置!$C26)) | U15: =IF(B15="未启用","",I15*IF(D15="是",V6设置!$D18,V6设置!$D26))
A16: 12 | B16: =V6周期计划!B31 -> 未启用 | C16: =IF(B16="未启用","",V6周期计划!C31) | D16: =IF(B16="未启用","",V6周期计划!D31) | E16: =IF(B16="未启用","",V6周期计划!E31) | F16: =IF(B16="未启用","",V6周期计划!F31) | G16: =IF(B16="未启用","",V6周期计划!G31) | H16: =IF(B16="未启用","",V6周期计划!H31) | I16: =IF(B16="未启用","",V6周期计划!I31) | J16: =IF(B16="未启用","",G16*IF(D16="是",V6设置!$B15,V6设置!$B23)) | K16: =IF(B16="未启用","",H16*IF(D16="是",V6设置!$C15,V6设置!$C23)) | L16: =IF(B16="未启用","",I16*IF(D16="是",V6设置!$D15,V6设置!$D23)) | M16: =IF(B16="未启用","",G16*IF(D16="是",V6设置!$B16,V6设置!$B24)) | N16: =IF(B16="未启用","",H16*IF(D16="是",V6设置!$C16,V6设置!$C24)) | O16: =IF(B16="未启用","",I16*IF(D16="是",V6设置!$D16,V6设置!$D24)) | P16: =IF(B16="未启用","",G16*IF(D16="是",V6设置!$B17,V6设置!$B25)) | Q16: =IF(B16="未启用","",H16*IF(D16="是",V6设置!$C17,V6设置!$C25)) | R16: =IF(B16="未启用","",I16*IF(D16="是",V6设置!$D17,V6设置!$D25)) | S16: =IF(B16="未启用","",G16*IF(D16="是",V6设置!$B18,V6设置!$B26)) | T16: =IF(B16="未启用","",H16*IF(D16="是",V6设置!$C18,V6设置!$C26)) | U16: =IF(B16="未启用","",I16*IF(D16="是",V6设置!$D18,V6设置!$D26))
A17: 13 | B17: =V6周期计划!B32 -> 未启用 | C17: =IF(B17="未启用","",V6周期计划!C32) | D17: =IF(B17="未启用","",V6周期计划!D32) | E17: =IF(B17="未启用","",V6周期计划!E32) | F17: =IF(B17="未启用","",V6周期计划!F32) | G17: =IF(B17="未启用","",V6周期计划!G32) | H17: =IF(B17="未启用","",V6周期计划!H32) | I17: =IF(B17="未启用","",V6周期计划!I32) | J17: =IF(B17="未启用","",G17*IF(D17="是",V6设置!$B15,V6设置!$B23)) | K17: =IF(B17="未启用","",H17*IF(D17="是",V6设置!$C15,V6设置!$C23)) | L17: =IF(B17="未启用","",I17*IF(D17="是",V6设置!$D15,V6设置!$D23)) | M17: =IF(B17="未启用","",G17*IF(D17="是",V6设置!$B16,V6设置!$B24)) | N17: =IF(B17="未启用","",H17*IF(D17="是",V6设置!$C16,V6设置!$C24)) | O17: =IF(B17="未启用","",I17*IF(D17="是",V6设置!$D16,V6设置!$D24)) | P17: =IF(B17="未启用","",G17*IF(D17="是",V6设置!$B17,V6设置!$B25)) | Q17: =IF(B17="未启用","",H17*IF(D17="是",V6设置!$C17,V6设置!$C25)) | R17: =IF(B17="未启用","",I17*IF(D17="是",V6设置!$D17,V6设置!$D25)) | S17: =IF(B17="未启用","",G17*IF(D17="是",V6设置!$B18,V6设置!$B26)) | T17: =IF(B17="未启用","",H17*IF(D17="是",V6设置!$C18,V6设置!$C26)) | U17: =IF(B17="未启用","",I17*IF(D17="是",V6设置!$D18,V6设置!$D26))
A18: 14 | B18: =V6周期计划!B33 -> 未启用 | C18: =IF(B18="未启用","",V6周期计划!C33) | D18: =IF(B18="未启用","",V6周期计划!D33) | E18: =IF(B18="未启用","",V6周期计划!E33) | F18: =IF(B18="未启用","",V6周期计划!F33) | G18: =IF(B18="未启用","",V6周期计划!G33) | H18: =IF(B18="未启用","",V6周期计划!H33) | I18: =IF(B18="未启用","",V6周期计划!I33) | J18: =IF(B18="未启用","",G18*IF(D18="是",V6设置!$B15,V6设置!$B23)) | K18: =IF(B18="未启用","",H18*IF(D18="是",V6设置!$C15,V6设置!$C23)) | L18: =IF(B18="未启用","",I18*IF(D18="是",V6设置!$D15,V6设置!$D23)) | M18: =IF(B18="未启用","",G18*IF(D18="是",V6设置!$B16,V6设置!$B24)) | N18: =IF(B18="未启用","",H18*IF(D18="是",V6设置!$C16,V6设置!$C24)) | O18: =IF(B18="未启用","",I18*IF(D18="是",V6设置!$D16,V6设置!$D24)) | P18: =IF(B18="未启用","",G18*IF(D18="是",V6设置!$B17,V6设置!$B25)) | Q18: =IF(B18="未启用","",H18*IF(D18="是",V6设置!$C17,V6设置!$C25)) | R18: =IF(B18="未启用","",I18*IF(D18="是",V6设置!$D17,V6设置!$D25)) | S18: =IF(B18="未启用","",G18*IF(D18="是",V6设置!$B18,V6设置!$B26)) | T18: =IF(B18="未启用","",H18*IF(D18="是",V6设置!$C18,V6设置!$C26)) | U18: =IF(B18="未启用","",I18*IF(D18="是",V6设置!$D18,V6设置!$D26))
A19: 15 | B19: =V6周期计划!B34 -> 未启用 | C19: =IF(B19="未启用","",V6周期计划!C34) | D19: =IF(B19="未启用","",V6周期计划!D34) | E19: =IF(B19="未启用","",V6周期计划!E34) | F19: =IF(B19="未启用","",V6周期计划!F34) | G19: =IF(B19="未启用","",V6周期计划!G34) | H19: =IF(B19="未启用","",V6周期计划!H34) | I19: =IF(B19="未启用","",V6周期计划!I34) | J19: =IF(B19="未启用","",G19*IF(D19="是",V6设置!$B15,V6设置!$B23)) | K19: =IF(B19="未启用","",H19*IF(D19="是",V6设置!$C15,V6设置!$C23)) | L19: =IF(B19="未启用","",I19*IF(D19="是",V6设置!$D15,V6设置!$D23)) | M19: =IF(B19="未启用","",G19*IF(D19="是",V6设置!$B16,V6设置!$B24)) | N19: =IF(B19="未启用","",H19*IF(D19="是",V6设置!$C16,V6设置!$C24)) | O19: =IF(B19="未启用","",I19*IF(D19="是",V6设置!$D16,V6设置!$D24)) | P19: =IF(B19="未启用","",G19*IF(D19="是",V6设置!$B17,V6设置!$B25)) | Q19: =IF(B19="未启用","",H19*IF(D19="是",V6设置!$C17,V6设置!$C25)) | R19: =IF(B19="未启用","",I19*IF(D19="是",V6设置!$D17,V6设置!$D25)) | S19: =IF(B19="未启用","",G19*IF(D19="是",V6设置!$B18,V6设置!$B26)) | T19: =IF(B19="未启用","",H19*IF(D19="是",V6设置!$C18,V6设置!$C26)) | U19: =IF(B19="未启用","",I19*IF(D19="是",V6设置!$D18,V6设置!$D26))
A20: 16 | B20: =V6周期计划!B35 -> 未启用 | C20: =IF(B20="未启用","",V6周期计划!C35) | D20: =IF(B20="未启用","",V6周期计划!D35) | E20: =IF(B20="未启用","",V6周期计划!E35) | F20: =IF(B20="未启用","",V6周期计划!F35) | G20: =IF(B20="未启用","",V6周期计划!G35) | H20: =IF(B20="未启用","",V6周期计划!H35) | I20: =IF(B20="未启用","",V6周期计划!I35) | J20: =IF(B20="未启用","",G20*IF(D20="是",V6设置!$B15,V6设置!$B23)) | K20: =IF(B20="未启用","",H20*IF(D20="是",V6设置!$C15,V6设置!$C23)) | L20: =IF(B20="未启用","",I20*IF(D20="是",V6设置!$D15,V6设置!$D23)) | M20: =IF(B20="未启用","",G20*IF(D20="是",V6设置!$B16,V6设置!$B24)) | N20: =IF(B20="未启用","",H20*IF(D20="是",V6设置!$C16,V6设置!$C24)) | O20: =IF(B20="未启用","",I20*IF(D20="是",V6设置!$D16,V6设置!$D24)) | P20: =IF(B20="未启用","",G20*IF(D20="是",V6设置!$B17,V6设置!$B25)) | Q20: =IF(B20="未启用","",H20*IF(D20="是",V6设置!$C17,V6设置!$C25)) | R20: =IF(B20="未启用","",I20*IF(D20="是",V6设置!$D17,V6设置!$D25)) | S20: =IF(B20="未启用","",G20*IF(D20="是",V6设置!$B18,V6设置!$B26)) | T20: =IF(B20="未启用","",H20*IF(D20="是",V6设置!$C18,V6设置!$C26)) | U20: =IF(B20="未启用","",I20*IF(D20="是",V6设置!$D18,V6设置!$D26))
A21: 17 | B21: =V6周期计划!B36 -> 未启用 | C21: =IF(B21="未启用","",V6周期计划!C36) | D21: =IF(B21="未启用","",V6周期计划!D36) | E21: =IF(B21="未启用","",V6周期计划!E36) | F21: =IF(B21="未启用","",V6周期计划!F36) | G21: =IF(B21="未启用","",V6周期计划!G36) | H21: =IF(B21="未启用","",V6周期计划!H36) | I21: =IF(B21="未启用","",V6周期计划!I36) | J21: =IF(B21="未启用","",G21*IF(D21="是",V6设置!$B15,V6设置!$B23)) | K21: =IF(B21="未启用","",H21*IF(D21="是",V6设置!$C15,V6设置!$C23)) | L21: =IF(B21="未启用","",I21*IF(D21="是",V6设置!$D15,V6设置!$D23)) | M21: =IF(B21="未启用","",G21*IF(D21="是",V6设置!$B16,V6设置!$B24)) | N21: =IF(B21="未启用","",H21*IF(D21="是",V6设置!$C16,V6设置!$C24)) | O21: =IF(B21="未启用","",I21*IF(D21="是",V6设置!$D16,V6设置!$D24)) | P21: =IF(B21="未启用","",G21*IF(D21="是",V6设置!$B17,V6设置!$B25)) | Q21: =IF(B21="未启用","",H21*IF(D21="是",V6设置!$C17,V6设置!$C25)) | R21: =IF(B21="未启用","",I21*IF(D21="是",V6设置!$D17,V6设置!$D25)) | S21: =IF(B21="未启用","",G21*IF(D21="是",V6设置!$B18,V6设置!$B26)) | T21: =IF(B21="未启用","",H21*IF(D21="是",V6设置!$C18,V6设置!$C26)) | U21: =IF(B21="未启用","",I21*IF(D21="是",V6设置!$D18,V6设置!$D26))
